Workbook

Sheet Jeanre Transactional
A1: Movement | B1: Account Secondary | C1: 2024-05-01 | D1: 2024-06-01 | E1: 2024-07-01 | F1: 2024-08-01 | G1: 2024-09-01 | H1: 2024-10-01 | I1: 2024-11-01 | J1: 2024-12-01 | K1: 2025-01-01 | L1: 2025-02-01 | M1: 2025-03-01 | N1: 2025-04-01 | O1: 2025-05-01 | P1: 2025-06-01 | Q1: 2025-07-01 | R1: 2025-08-01 | S1: 2025-09-01 | T1: 2025-10-01 | U1: 2025-11-01 | V1: 2025-12-01
A2: Credit | B2: Salary | C2: 27000 | D2: 27000 | E2: 21600 | F2: 21600 | G2: 21600 | H2: 21600 | I2: 21600 | J2: 25100 | K2: 25100 | L2: 21600 | N2: 21600 | O2: 21600 | P2: 21600 | Q2: 21600 | R2: 21600 | S2: 21600 | T2: 21600 | U2: 21600 | V2: 21600
A3: Credit | B3: Bicycle Claims | C3: 1325 | D3: 1325 | E3: 1325 | F3: 1325 | G3: 1325 | H3: 1000 | I3: 1000 | J3: 1169 | K3: 1169 | L3: 1169 | N3: 1169 | O3: 1169 | P3: 1169 | Q3: 1169 | R3: 1169 | S3: 1169 | T3: 1169 | U3: 1169 | V3: 1169
A4: Credit | B4: Jodine Transactional | F4: 750 | G4: 1250 | I4: 250
A5: Credit | B5: Other | N5: 1000 | O5: 1000 | P5: 1000 | Q5: 1000 | R5: 1000 | S5: 1000 | T5: 1000 | U5: 1000 | V5: 1000
A6: Credit | B6: Personal Wealth | H6: 0 | I6: 3500
A7: Credit | B7: Retained Balance | M7: =jtrn[[#Totals],[2025-02-01]] -> 10 | N7: =jtrn[[#Totals],[2025-03-01]] -> -29909 | O7: =jtrn[[#Totals],[2025-04-01]] -> -30259 | P7: =jtrn[[#Totals],[2025-05-01]] -> -30609 | Q7: =jtrn[[#Totals],[2025-06-01]] -> -30959 | R7: =jtrn[[#Totals],[2025-07-01]] -> -31939 | S7: =jtrn[[#Totals],[2025-08-01]] -> -32289 | T7: =jtrn[[#Totals],[2025-09-01]] -> -27639 | U7: =jtrn[[#Totals],[2025-10-01]] -> -27989 | V7: =jtrn[[#Totals],[2025-11-01]] -> -30339
A8: Credit | B8: Tax Refund | G8: 5700 | S8: 5000
A9: Credit | B9: Bernice Transactional | C9: 7700 | D9: 7700 | E9: 7000 | F9: 6800 | G9: 7000 | H9: 7300 | I9: 7750 | J9: 8000 | K9: 8000 | L9: 7700 | N9: 7700 | O9: 7700 | P9: 7700 | Q9: 7700 | R9: 7700 | S9: 7700 | T9: 7700 | U9: 7700 | V9: 7700
A10: Debit | B10: Jeanre Credit Card | C10: 500 | D10: 1500 | E10: 250 | F10: 500 | G10: 500 | H10: 1000 | I10: 750 | J10: 1000 | K10: 1000 | L10: 1000 | N10: 1900 | O10: 1900 | P10: 1900 | Q10: 1900 | R10: 1900 | S10: 1900 | T10: 1900 | U10: 1900 | V10: 1900
A11: Debit | B11: Home Loan | C11: 8140 | D11: 8140 | E11: 8140 | F11: 8140 | G11: 8140 | H11: 8140 | I11: 8140 | J11: 8140 | K11: 8140 | L11: 7910 | M11: 7910 | N11: 7910 | O11: 7910 | P11: 7910 | Q11: 7910 | R11: 7910 | S11: 7910 | T11: 7910 | U11: 7910 | V11: 7910
A12: Debit | B12: Vehicle Loan | C12: 3500 | D12: 3578 | E12: 3578 | F12: 3578 | G12: 3578 | H12: 3578 | I12: 3578 | J12: 3578 | K12: 3578 | L12: 3577 | M12: 3577 | N12: 3577 | O12: 3577 | P12: 3577 | Q12: 3577 | R12: 3577 | S12: 3577 | T12: 3577 | U12: 3577 | V12: 3577
A13: Debit | B13: Medical Aid | C13: 4530 | D13: 4530 | E13: 4530 | F13: 4530 | G13: 5600 | H13: 5600 | I13: 5600 | J13: 5600 | K13: 5600 | L13: 6305 | M13: 6305 | N13: 6305 | O13: 6305 | P13: 6305 | Q13: 6305 | R13: 6305 | S13: 6305 | T13: 6305 | U13: 6305 | V13: 6305
A14: Debit | B14: Netstar | C14: 110 | D14: 170 | E14: 170 | F14: 170 | G14: 170 | H14: 170 | I14: 170 | J14: 170 | K14: 170 | L14: 170
A15: Debit | B15: Shortfall Insurance | C15: 117 | D15: 117 | E15: 117 | F15: 117 | G15: 117 | H15: 117 | I15: 117 | J15: 117 | K15: 117 | L15: 117 | M15: 117 | N15: 117 | O15: 117 | P15: 117 | Q15: 117 | R15: 117 | S15: 117 | T15: 117 | U15: 117 | V15: 117
A16: Debit | B16: Vehicle Insurance | C16: 1050 | D16: 988 | E16: 988 | F16: 988 | G16: 988 | H16: 988 | I16: 988 | J16: 988 | K16: 988 | L16: 988 | M16: 750 | N16: 750 | O16: 750 | P16: 750 | Q16: 750 | R16: 750 | S16: 750 | T16: 750 | U16: 750 | V16: 750
A17: Debit | B17: Home Insurance | C17: 1200 | D17: 560 | E17: 560 | F17: 560 | G17: 560 | H17: 560 | I17: 610 | J17: 610 | K17: 610 | L17: 610 | M17: 610 | N17: 610 | O17: 610 | P17: 610 | Q17: 610 | R17: 610 | S17: 610 | T17: 610 | U17: 610 | V17: 610
A18: Debit | B18: Life Insurance | C18: 440 | D18: 440 | E18: 440 | F18: 440 | G18: 440 | H18: 440 | I18: 440 | J18: 440 | K18: 440 | L18: 450 | M18: 450 | N18: 450 | O18: 450 | P18: 450 | Q18: 450 | R18: 450 | S18: 450 | T18: 450 | U18: 450 | V18: 450
A19: Debit | B19: Municipal Account | C19: 3500 | D19: 3500 | E19: 3500 | F19: 3500 | G19: 3500 | H19: 4000 | I19: 4000 | J19: 3700 | K19: 3700 | L19: 3000 | M19: 3700 | N19: 3700 | O19: 3700 | P19: 3700 | Q19: 3700 | R19: 3700 | S19: 3700 | T19: 3700 | U19: 3700 | V19: 3700
A20: Debit | B20: Internet | C20: 1000 | D20: 1000 | E20: 1000 | F20: 1000 | G20: 1000 | H20: 1000 | I20: 1000 | J20: 1000 | K20: 1000 | L20: 1000 | M20: 1000 | N20: 1000 | O20: 1000 | P20: 1000 | Q20: 1000 | R20: 1000 | S20: 1000 | T20: 1000 | U20: 1000 | V20: 1000
A21: Debit | B21: Fuel | C21: 1000 | D21: 1500 | E21: 250 | F21: 500 | G21: 900 | H21: 200 | I21: 150 | J21: 900 | K21: 900 | L21: 500 | M21: 500 | N21: 500 | O21: 500 | P21: 500 | Q21: 500 | R21: 500 | S21: 500 | T21: 500 | U21: 500 | V21: 500
A22: Debit | B22: Running Costs | C22: 5000 | D22: 4300 | E22: 3000 | F22: 3500 | G22: 3200 | H22: 3000 | I22: 3500 | J22: 4000 | K22: 4000 | L22: 2600 | M22: 3700 | N22: 3700 | O22: 3700 | P22: 3700 | Q22: 3700 | R22: 3700 | S22: 3700 | T22: 3700 | U22: 3700 | V22: 3700
A23: Debit | B23: Administration | C23: 0 | D23: 0 | E23: 0 | F23: 0 | G23: 0 | H23: 0 | I23: 0 | J23: 0 | K23: 0
A24: Debit | B24: Jodine Transactional | C24: 500 | D24: 200 | F24: 0 | G24: 0 | H24: 0 | I24: 0 | J24: 0 | K24: 0
A25: Debit | B25: Jodine U | C25: 1000 | D25: 1000 | E25: 0 | G25: 500 | H25: 1000 | I25: 500 | J25: 500 | K25: 500
A26: Debit | B26: Emergency | C26: 200 | D26: 200 | E26: 200 | F26: 200 | G26: 200 | H26: 0 | I26: 200 | J26: 200 | K26: 200 | L26: 900 | M26: 200 | N26: 200 | O26: 200 | P26: 200 | Q26: 200 | R26: 200 | S26: 200 | T26: 200 | U26: 200 | V26: 200
A27: Debit | B27: Jeanre Retirement | C27: 0 | D27: 0 | E27: 0 | F27: 0 | G27: 0 | H27: 0 | I27: 0 | J27: 0 | K27: 0
A28: Debit | B28: Vehicle Licenses | E28: 640 | F28: 0 | G28: 0 | H28: 0 | I28: 0 | J28: 500 | K28: 500 | L28: 432 | Q28: 630
A29: Debit | B29: Other | E29: 600 | F29: 600 | H29: 580
A30: Debit | B30: Accounts | I30: 2227
A31: Debit | B31: Events | I31: 2065 | U31: 2000
A32: Debit | B32: Medical | M32: 900 | N32: 900 | O32: 900 | P32: 900 | Q32: 900 | R32: 900 | S32: 900 | T32: 900 | U32: 900 | V32: 900
A33: Debit | B33: Tax | F33: 500 | G33: 500
A34: Debit | B34: Cell Phones | C34: 3100 | D34: 1700 | E34: 1820 | F34: 1820 | G34: 0 | H34: 0 | I34: 0 | J34: 0 | K34: 0
A35: Debit | B35: Jansie | C35: 600 | D35: 600 | E35: 0 | F35: 0 | G35: 0 | H35: 0 | I35: 0 | J35: 0 | K35: 0
A36: Debit | B36: Vape
A37: Debit | B37: Gas | L37: 700
A38: Debit | B38: Personal Wealth | C38: 0 | D38: 500 | G38: 5000 | J38: 3000 | K38: 3000 | L38: 200 | M38: 200 | N38: 200 | O38: 200 | P38: 200 | Q38: 200 | R38: 200 | S38: 200 | T38: 200 | U38: 200 | V38: 200
A39: Subtotal | B39: Jeanre Transactional | C39: =SUMIF('Jeanre Transactional'!$A$2:$A$39,"Credit", 'Jeanre Transactional'!$C$2:$C$39)-SUMIF('Jeanre Transactional'!$A$2:$A$39,"Debit", 'Jeanre Transactional'!$C$2:$C$39) -> 538 | D39: =SUMIF('Jeanre Transactional'!$A$2:$A$39,"Credit", 'Jeanre Transactional'!$D$2:$D$39)-SUMIF('Jeanre Transactional'!$A$2:$A$39,"Debit", 'Jeanre Transactional'!$D$2:$D$39) -> 1502 | E39: =SUMIF('Jeanre Transactional'!$A$2:$A$39,"Credit", 'Jeanre Transactional'!$E$2:$E$39)-SUMIF('Jeanre Transactional'!$A$2:$A$39,"Debit", 'Jeanre Transactional'!$E$2:$E$39) -> 142 | F39: =SUMIF('Jeanre Transactional'!$A$2:$A$39,"Credit", 'Jeanre Transactional'!$F$2:$F$39)-SUMIF('Jeanre Transactional'!$A$2:$A$39,"Debit", 'Jeanre Transactional'!$F$2:$F$39) -> -168 | G39: =SUMIF('Jeanre Transactional'!$A$2:$A$39,"Credit", 'Jeanre Transactional'!$G$2:$G$39)-SUMIF('Jeanre Transactional'!$A$2:$A$39,"Debit", 'Jeanre Transactional'!$G$2:$G$39) -> 1982 | H39: =SUMIF('Jeanre Transactional'!$A$2:$A$39,"Credit", 'Jeanre Transactional'!$H$2:$H$39)-SUMIF('Jeanre Transactional'!$A$2:$A$39,"Debit", 'Jeanre Transactional'!$H$2:$H$39) -> -473 | I39: =SUMIF('Jeanre Transactional'!$A$2:$A$39,"Credit", 'Jeanre Transactional'!$I$2:$I$39)-SUMIF('Jeanre Transactional'!$A$2:$A$39,"Debit", 'Jeanre Transactional'!$I$2:$I$39) -> 65 | J39: =SUMIF('Jeanre Transactional'!$A$2:$A$39,"Credit", 'Jeanre Transactional'!$J$2:$J$39)-SUMIF('Jeanre Transactional'!$A$2:$A$39,"Debit", 'Jeanre Transactional'!$J$2:$J$39) -> -174 | K39: =SUMIF(jtrn[Movement], "Credit", jtrn[2025-01-01]) - SUMIF(jtrn[Movement], "Debit", jtrn[2025-01-01]) -> -174 | L39: =SUMIF(jtrn[Movement], "Credit", jtrn[2025-02-01]) - SUMIF(jtrn[Movement], "Debit", jtrn[2025-02-01]) -> 10 | M39: =SUMIF(jtrn[Movement], "Credit", jtrn[2025-03-01]) - SUMIF(jtrn[Movement], "Debit", jtrn[2025-03-01]) -> -29909 | N39: =SUMIF(jtrn[Movement], "Credit", jtrn[2025-04-01]) - SUMIF(jtrn[Movement], "Debit", jtrn[2025-04-01]) -> -30259 | O39: =SUMIF(jtrn[Movement], "Credit", jtrn[2025-05-01]) - SUMIF(jtrn[Movement], "Debit", jtrn[2025-05-01]) -> -30609 | P39: =SUMIF(jtrn[Movement], "Credit", jtrn[2025-06-01]) - SUMIF(jtrn[Movement], "Debit", jtrn[2025-06-01]) -> -30959 | Q39: =SUMIF(jtrn[Movement], "Credit", jtrn[2025-07-01]) - SUMIF(jtrn[Movement], "Debit", jtrn[2025-07-01]) -> -31939 | R39: =SUMIF(jtrn[Movement], "Credit", jtrn[2025-08-01]) - SUMIF(jtrn[Movement], "Debit", jtrn[2025-08-01]) -> -32289 | S39: =SUMIF(jtrn[Movement], "Credit", jtrn[2025-09-01]) - SUMIF(jtrn[Movement], "Debit", jtrn[2025-09-01]) -> -27639 | T39: =SUMIF(jtrn[Movement], "Credit", jtrn[2025-10-01]) - SUMIF(jtrn[Movement], "Debit", jtrn[2025-10-01]) -> -27989 | U39: =SUMIF(jtrn[Movement], "Credit", jtrn[2025-11-01]) - SUMIF(jtrn[Movement], "Debit", jtrn[2025-11-01]) -> -30339 | V39: =SUMIF(jtrn[Movement], "Credit", jtrn[2025-12-01]) - SUMIF(jtrn[Movement], "Debit", jtrn[2025-12-01]) -> -30689
AJ41: 1
...

Sheet Sheet1
A1: 1 dollar app
A2: I need 1500 dollars a month at least
A4: meaning I need to sell 1500 copies a month.
A6: also we can make 10cents per ad impression(lowest)
A7: so we need 15000 ad impressions a month.
A8: that is ±485 ad impressions a day.
A9: if the average user uses receives 2 ad impressions a day
A10: we need upwards of 250 users. | B10: this might be doable...

Sheet Bernice Transactional
A1: Movement | B1: Account Secondary | C1: 2024-05-01 | D1: 2024-06-01 | E1: 2024-07-01 | F1: 2024-08-01 | G1: 2024-09-01 | H1: 2024-10-01 | I1: 2024-11-01 | J1: 2024-12-01 | K1: 2024-12-02 | L1: 2025-01-01 | M1: 2025-02-01 | N1: 2025-03-01 | O1: 2025-04-01 | P1: 2025-05-01 | Q1: 2025-06-01 | R1: 2025-07-01 | S1: 2025-08-01 | T1: 2025-09-01 | U1: 2025-10-01 | V1: 2025-11-01 | W1: 2025-12-01
A2: Credit | B2: Salary | C2: 11000 | D2: 11000 | E2: 8800 | F2: 8800 | G2: 8800 | H2: 8800 | I2: 8800 | J2: 11300 | K2: 11300 | M2: 8800 | N2: 8800 | O2: 8800 | P2: 8800 | Q2: 8800 | R2: 8800 | S2: 8800 | T2: 8800 | U2: 8800 | V2: 8800 | W2: 8800
A3: Credit | B3: Retained Balance | M3: 350 | N3: =M12 -> 350 | O3: =N12 -> 350 | P3: =O12 -> 350 | Q3: =P12 -> 350 | R3: =Q12 -> 350 | S3: =R12 -> 350 | T3: =S12 -> 350 | U3: =T12 -> 350 | ... W3: =V12 -> 350
A4: Debit | B4: Bernice Credit Card | C4: 2000 | D4: 2000 | E4: 500 | F4: 500 | G4: 500 | H4: 500 | I4: 700 | J4: 2200 | K4: 2200 | M4: 900 | N4: 900 | O4: 900 | P4: 900 | Q4: 900 | R4: 900 | S4: 900 | T4: 900 | U4: 900 | V4: 900 | W4: 900
A5: Debit | B5: Jeanre Transactional | C5: 7700 | D5: 7700 | E5: 7000 | F5: 6800 | G5: 7000 | H5: 7300 | I5: 7750 | J5: 8000 | K5: 8000 | M5: 7700 | N5: 7700 | O5: 7700 | P5: 7700 | Q5: 7700 | R5: 7700 | S5: 7700 | T5: 7700 | U5: 7700 | V5: 7700 | W5: 7700
A6: Debit | B6: Geely Insurance | C6: 110 | D6: 110 | E6: 110 | F6: 110 | G6: 110 | H6: 110 | I6: 110 | J6: 110 | K6: 110
A7: Debit | B7: Medical | C7: 900 | D7: 900 | E7: 900 | F7: 900
A8: Debit | B8: Bernice Retirement | C8: 0 | D8: 0 | E8: 0 | F8: 0 | G8: 0 | H8: 0 | I8: 0 | J8: 0 | K8: 0
A9: Debit | B9: Bernice Personal Savings | C9: 0 | D9: 200 | E9: 200 | F9: 200 | G9: 200 | H9: 200 | I9: 200 | J9: 200 | K9: 200 | M9: 200 | N9: 200 | O9: 200 | P9: 200 | Q9: 200 | R9: 200 | S9: 200 | T9: 200 | U9: 200 | V9: 200 | W9: 200
A10: Debit | B10: Comic Con | H10: 607
A11: Debit | B11: Home and Vehicle Savings | C11: 0 | D11: 0 | E11: 0 | F11: 0 | G11: 0 | H11: 0 | I11: 0 | J11: 0 | K11: 0
A12: Subtotal | B12: Bernice Transactional | C12: =SUMIF(btrn[[Movement]:[Movement]],"Credit", btrn[2024-05-01])-SUMIF(btrn[[Movement]:[Movement]],"Debit",btrn[2024-05-01]) -> 290 | D12: =SUMIF(btrn[[Movement]:[Movement]],"Credit", btrn[2024-06-01])-SUMIF(btrn[[Movement]:[Movement]],"Debit",btrn[2024-06-01]) -> 90 | E12: =SUMIF(btrn[[Movement]:[Movement]],"Credit", btrn[2024-07-01])-SUMIF(btrn[[Movement]:[Movement]],"Debit",btrn[2024-07-01]) -> 90 | F12: =SUMIF(btrn[[Movement]:[Movement]],"Credit", btrn[2024-08-01])-SUMIF(btrn[[Movement]:[Movement]],"Debit",btrn[2024-08-01]) -> 290 | G12: =SUMIF(btrn[[Movement]:[Movement]],"Credit", btrn[2024-09-01])-SUMIF(btrn[[Movement]:[Movement]],"Debit",btrn[2024-09-01]) -> 990 | H12: =SUMIF(btrn[[Movement]:[Movement]],"Credit", btrn[2024-10-01])-SUMIF(btrn[[Movement]:[Movement]],"Debit",btrn[2024-10-01]) -> 83 | I12: =SUMIF(btrn[[Movement]:[Movement]],"Credit", btrn[2024-11-01])-SUMIF(btrn[[Movement]:[Movement]],"Debit",btrn[2024-11-01]) -> 40 | J12: =SUMIF(btrn[[Movement]:[Movement]],"Credit", btrn[2024-12-01])-SUMIF(btrn[[Movement]:[Movement]],"Debit",btrn[2024-12-01]) -> 790 | K12: =SUMIF(btrn[[Movement]:[Movement]],"Credit", btrn[2024-12-02])-SUMIF(btrn[[Movement]:[Movement]],"Debit",btrn[2024-12-02]) -> 790 | M12: =SUMIF(btrn[Movement], "Credit", btrn[2025-02-01]) - SUMIF(btrn[Movement], "Debit", btrn[2025-02-01]) -> 350 | N12: =SUMIF(btrn[Movement], "Credit", btrn[2025-03-01]) - SUMIF(btrn[Movement], "Debit", btrn[2025-03-01]) -> 350 | O12: =SUMIF(btrn[Movement], "Credit", btrn[2025-04-01]) - SUMIF(btrn[Movement], "Debit", btrn[2025-04-01]) -> 350 | P12: =SUMIF(btrn[Movement], "Credit", btrn[2025-05-01]) - SUMIF(btrn[Movement], "Debit", btrn[2025-05-01]) -> 350 | Q12: =SUMIF(btrn[Movement], "Credit", btrn[2025-06-01]) - SUMIF(btrn[Movement], "Debit", btrn[2025-06-01]) -> 350 | R12: =SUMIF(btrn[Movement], "Credit", btrn[2025-07-01]) - SUMIF(btrn[Movement], "Debit", btrn[2025-07-01]) -> 350 | S12: =SUMIF(btrn[Movement], "Credit", btrn[2025-08-01]) - SUMIF(btrn[Movement], "Debit", btrn[2025-08-01]) -> 350 | T12: =SUMIF(btrn[Movement], "Credit", btrn[2025-09-01]) - SUMIF(btrn[Movement], "Debit", btrn[2025-09-01]) -> 350 | U12: =SUMIF(btrn[Movement], "Credit", btrn[2025-10-01]) - SUMIF(btrn[Movement], "Debit", btrn[2025-10-01]) -> 350 | V12: =SUMIF(btrn[Movement], "Credit", btrn[2025-11-01]) - SUMIF(btrn[Movement], "Debit", btrn[2025-11-01]) -> 350 | W12: =SUMIF(btrn[Movement], "Credit", btrn[2025-12-01]) - SUMIF(btrn[Movement], "Debit", btrn[2025-12-01]) -> 350

Sheet Bernice Credit Card
A1: Item | B1: Amount
A2: Interest NACM | B2: 0.1675
A3: Interst Monthly | B3: =B2/12 -> 0.013958333
A7: Movement | B7: Account Secondary | C7: 2024-05-01 | D7: 2024-06-01 | E7: 2024-07-01 | F7: 2024-08-01 | G7: 2024-09-01 | H7: 2024-10-01 | I7: 2024-11-01 | J7: 2024-12-01 | K7: 2025-02-01 | L7: 2025-03-01 | M7: 2025-04-01 | N7: 2025-05-01 | O7: 2025-06-01 | P7: 2025-07-01 | Q7: 2025-08-01 | R7: 2025-09-01 | S7: 2025-10-01 | T7: 2025-11-01 | U7: 2025-12-01
A8: Credit | B8: Bernice Transactional | C8: 2000 | D8: 0 | E8: 500 | F8: 500 | G8: 500 | H8: 500 | I8: 500 | J8: 500 | K8: 900 | L8: 900 | M8: 900 | N8: 900 | O8: 900 | P8: 900 | Q8: 900 | R8: 900 | S8: 900 | T8: 900 | U8: 900
A9: Credit | B9: Retained Balance | K9: -30 | L9: =K16 -> -5230 | M9: =L16 -> -4403.0021 | N9: =M16 -> -3564.4607 | O9: =N16 -> -2714.2146 | P9: =O16 -> -1852.1005 | Q9: =P16 -> -977.95273 | R9: =Q16 -> -3591.6033 | S9: =R16 -> -2741.7361 | ... U9: =T16 -> -1006.2479
A10: Debit | B10: Interest | L10: =IF(L9 <= 0, (L9*$B$3)*-1, 0) -> 73.002083 | M10: =IF(M9 <= 0, (M9*$B$3)*-1, 0) -> 61.458571 | N10: =IF(N9 <= 0, (N9*$B$3)*-1, 0) -> 49.75393 | O10: =IF(O9 <= 0, (O9*$B$3)*-1, 0) -> 37.885912 | P10: =IF(P9 <= 0, (P9*$B$3)*-1, 0) -> 25.852236 | Q10: =IF(Q9 <= 0, (Q9*$B$3)*-1, 0) -> 13.65059 | R10: =IF(R9 <= 0, (R9*$B$3)*-1, 0) -> 50.132796 | S10: =IF(S9 <= 0, (S9*$B$3)*-1, 0) -> 38.270067 | ... U10: =IF(U9 <= 0, (U9*$B$3)*-1, 0) -> 14.045544
A11: Debit | B11: Bulk Meat | E11: 3550 | K11: 3500 | Q11: 3500
A12: Debit | B12: Geely Parts | K12: 1600
A13: Debit | B13: Other | C13: 0 | D13: 0 | E13: 0 | F13: 0 | G13: 0 | H13: 0 | I13: 0 | J13: 0 | K13: 1000
A14: Debit
A15: Debit
A16: Subtotal | B16: Bernice Credit Card | C16: =SUMIF(bcc_1[[Movement]:[Movement]],"Credit", bcc_1[2024-05-01])-SUMIF(bcc_1[[Movement]:[Movement]],"Debit",bcc_1[2024-05-01]) -> 2000 | D16: =SUMIF(bcc_1[[Movement]:[Movement]],"Credit", bcc_1[2024-06-01])-SUMIF(bcc_1[[Movement]:[Movement]],"Debit",bcc_1[2024-06-01]) -> 0 | E16: =SUMIF(bcc_1[[Movement]:[Movement]],"Credit", bcc_1[2024-07-01])-SUMIF(bcc_1[[Movement]:[Movement]],"Debit",bcc_1[2024-07-01]) -> -3050 | F16: =SUMIF(bcc_1[[Movement]:[Movement]],"Credit", bcc_1[2024-08-01])-SUMIF(bcc_1[[Movement]:[Movement]],"Debit",bcc_1[2024-08-01]) -> 500 | G16: =SUMIF(bcc_1[[Movement]:[Movement]],"Credit", bcc_1[2024-09-01])-SUMIF(bcc_1[[Movement]:[Movement]],"Debit",bcc_1[2024-09-01]) -> 500 | H16: =SUMIF(bcc_1[[Movement]:[Movement]],"Credit", bcc_1[2024-10-01])-SUMIF(bcc_1[[Movement]:[Movement]],"Debit",bcc_1[2024-10-01]) -> 500 | I16: =SUMIF(bcc_1[[Movement]:[Movement]],"Credit", bcc_1[2024-11-01])-SUMIF(bcc_1[[Movement]:[Movement]],"Debit",bcc_1[2024-11-01]) -> 500 | J16: =SUMIF(bcc_1[[Movement]:[Movement]],"Credit", bcc_1[2024-12-01])-SUMIF(bcc_1[[Movement]:[Movement]],"Debit",bcc_1[2024-12-01]) -> 500 | K16: =SUMIF(bcc_1[Movement], "Credit", bcc_1[2025-02-01]) - SUMIF(bcc_1[Movement], "Debit", bcc_1[2025-02-01]) -> -5230 | L16: =SUMIF(bcc_1[Movement], "Credit", bcc_1[2025-03-01]) - SUMIF(bcc_1[Movement], "Debit", bcc_1[2025-03-01]) -> -4403.0021 | M16: =SUMIF(bcc_1[Movement], "Credit", bcc_1[2025-04-01]) - SUMIF(bcc_1[Movement], "Debit", bcc_1[2025-04-01]) -> -3564.4607 | N16: =SUMIF(bcc_1[Movement], "Credit", bcc_1[2025-05-01]) - SUMIF(bcc_1[Movement], "Debit", bcc_1[2025-05-01]) -> -2714.2146 | O16: =SUMIF(bcc_1[Movement], "Credit", bcc_1[2025-06-01]) - SUMIF(bcc_1[Movement], "Debit", bcc_1[2025-06-01]) -> -1852.1005 | P16: =SUMIF(bcc_1[Movement], "Credit", bcc_1[2025-07-01]) - SUMIF(bcc_1[Movement], "Debit", bcc_1[2025-07-01]) -> -977.95273 | Q16: =SUMIF(bcc_1[Movement], "Credit", bcc_1[2025-08-01]) - SUMIF(bcc_1[Movement], "Debit", bcc_1[2025-08-01]) -> -3591.6033 | R16: =SUMIF(bcc_1[Movement], "Credit", bcc_1[2025-09-01]) - SUMIF(bcc_1[Movement], "Debit", bcc_1[2025-09-01]) -> -2741.7361 | S16: =SUMIF(bcc_1[Movement], "Credit", bcc_1[2025-10-01]) - SUMIF(bcc_1[Movement], "Debit", bcc_1[2025-10-01]) -> -1880.0062 | T16: =SUMIF(bcc_1[Movement], "Credit", bcc_1[2025-11-01]) - SUMIF(bcc_1[Movement], "Debit", bcc_1[2025-11-01]) -> -1006.2479 | U16: =SUMIF(bcc_1[Movement], "Credit", bcc_1[2025-12-01]) - SUMIF(bcc_1[Movement], "Debit", bcc_1[2025-12-01]) -> -120.29348
A17: Debit Total | B17: Bernice Credit Card | K17: =SUMIF(bcc_1[Movement], "Debit", bcc_1[2025-02-01]) -> 6100 | L17: =SUMIF(bcc_1[Movement], "Debit", bcc_1[2025-03-01]) -> 73.002083 | M17: =SUMIF(bcc_1[Movement], "Debit", bcc_1[2025-04-01]) -> 61.458571 | N17: =SUMIF(bcc_1[Movement], "Debit", bcc_1[2025-05-01]) -> 49.75393 | O17: =SUMIF(bcc_1[Movement], "Debit", bcc_1[2025-06-01]) -> 37.885912 | P17: =SUMIF(bcc_1[Movement], "Debit", bcc_1[2025-07-01]) -> 25.852236 | Q17: =SUMIF(bcc_1[Movement], "Debit", bcc_1[2025-08-01]) -> 3513.6506 | R17: =SUMIF(bcc_1[Movement], "Debit", bcc_1[2025-09-01]) -> 50.132796 | S17: =SUMIF(bcc_1[Movement], "Debit", bcc_1[2025-10-01]) -> 38.270067 | T17: =SUMIF(bcc_1[Movement], "Debit", bcc_1[2025-11-01]) -> 26.241753 | U17: =SUMIF(bcc_1[Movement], "Debit", bcc_1[2025-12-01]) -> 14.045544

Sheet Jeanre Credit Card 
A1: Item | B1: Amount
A2: Interest NACM | B2: 0.2115
A3: Interst Monthly | B3: =B2/12 -> 0.017625
A7: Movement | B7: Account Secondary | C7: 2024-05-01 | D7: 2024-06-01 | E7: 2024-07-01 | F7: 2024-08-01 | G7: 2024-09-01 | H7: 2024-10-01 | I7: 2024-11-01 | J7: 2024-12-01 | K7: 2025-02-01 | L7: 2025-03-01 | M7: 2025-04-01 | N7: 2025-05-01 | O7: 2025-06-01 | P7: 2025-07-01 | Q7: 2025-08-01 | R7: 2025-09-01 | S7: 2025-10-01 | T7: 2025-11-01 | U7: 2025-12-01
A8: Credit | B8: Jeanre Transactional | C8: 2000 | D8: 0 | E8: 500 | F8: 500 | G8: 500 | H8: 500 | I8: 500 | J8: 500 | K8: 1000 | L8: 1900 | M8: 1900 | N8: 1900 | O8: 1900 | P8: 1900 | Q8: 1900 | R8: 1900 | S8: 1900 | T8: 1900 | U8: 1900
A9: Credit | B9: Retained Balance | K9: -9156 | L9: =K16 -> -8980 | M9: =L16 -> -8062.2725 | N9: =M16 -> -7128.3701 | O9: =N16 -> -6178.0076 | P9: =O16 -> -5210.895 | Q9: =P16 -> -4226.737 | R9: =Q16 -> -3225.2332 | S9: =R16 -> -2206.078 | ... U9: =T16 -> -113.563
A10: Debit | B10: Interest | L10: =IF(L9 <= 0, (L9*$B$3)*-1, 0) -> 158.2725 | M10: =IF(M9 <= 0, (M9*$B$3)*-1, 0) -> 142.09755 | N10: =IF(N9 <= 0, (N9*$B$3)*-1, 0) -> 125.63752 | O10: =IF(O9 <= 0, (O9*$B$3)*-1, 0) -> 108.88738 | P10: =IF(P9 <= 0, (P9*$B$3)*-1, 0) -> 91.842024 | Q10: =IF(Q9 <= 0, (Q9*$B$3)*-1, 0) -> 74.496239 | R10: =IF(R9 <= 0, (R9*$B$3)*-1, 0) -> 56.844736 | S10: =IF(S9 <= 0, (S9*$B$3)*-1, 0) -> 38.882124 | ... U10: =IF(U9 <= 0, (U9*$B$3)*-1, 0) -> 2.0015479
A11: Debit | B11: Apple One | E11: 3550 | K11: 230 | L11: 230 | M11: 230 | N11: 230 | O11: 230 | P11: 230 | Q11: 230 | R11: 230 | S11: 230 | T11: 230 | U11: 230
A12: Debit | B12: Netflix | K12: 199 | L12: 199 | M12: 199 | N12: 199 | O12: 199 | P12: 199 | Q12: 199 | R12: 199 | S12: 199 | T12: 199 | U12: 199
A13: Debit | B13: GGServers | C13: 0 | D13: 0 | E13: 0 | F13: 0 | G13: 0 | H13: 0 | I13: 0 | J13: 0 | K13: 115 | L13: 115 | M13: 115 | N13: 115 | O13: 115 | P13: 115 | Q13: 115 | R13: 115 | S13: 115 | T13: 115 | U13: 115
A14: Debit | B14: Fees | K14: 105 | L14: 105 | M14: 105 | N14: 105 | O14: 105 | P14: 105 | Q14: 105 | R14: 105 | S14: 105 | T14: 105 | U14: 105
A15: Debit | B15: Fiddler | K15: 175 | L15: 175 | M15: 175 | N15: 175 | O15: 175 | P15: 175 | Q15: 175 | R15: 175 | S15: 175 | T15: 175 | U15: 175
A16: Subtotal | B16: Jeanre Credit Card | C16: =SUMIF(jcc[[Movement]:[Movement]],"Credit", jcc[2024-05-01])-SUMIF(jcc[[Movement]:[Movement]],"Debit",jcc[2024-05-01]) -> 2000 | D16: =SUMIF(jcc[[Movement]:[Movement]],"Credit", jcc[2024-06-01])-SUMIF(jcc[[Movement]:[Movement]],"Debit",jcc[2024-06-01]) -> 0 | E16: =SUMIF(jcc[[Movement]:[Movement]],"Credit", jcc[2024-07-01])-SUMIF(jcc[[Movement]:[Movement]],"Debit",jcc[2024-07-01]) -> -3050 | F16: =SUMIF(jcc[[Movement]:[Movement]],"Credit", jcc[2024-08-01])-SUMIF(jcc[[Movement]:[Movement]],"Debit",jcc[2024-08-01]) -> 500 | G16: =SUMIF(jcc[[Movement]:[Movement]],"Credit", jcc[2024-09-01])-SUMIF(jcc[[Movement]:[Movement]],"Debit",jcc[2024-09-01]) -> 500 | H16: =SUMIF(jcc[[Movement]:[Movement]],"Credit", jcc[2024-10-01])-SUMIF(jcc[[Movement]:[Movement]],"Debit",jcc[2024-10-01]) -> 500 | I16: =SUMIF(jcc[[Movement]:[Movement]],"Credit", jcc[2024-11-01])-SUMIF(jcc[[Movement]:[Movement]],"Debit",jcc[2024-11-01]) -> 500 | J16: =SUMIF(jcc[[Movement]:[Movement]],"Credit", jcc[2024-12-01])-SUMIF(jcc[[Movement]:[Movement]],"Debit",jcc[2024-12-01]) -> 500 | K16: =SUMIF(jcc[Movement], "Credit", jcc[2025-02-01]) - SUMIF(jcc[Movement], "Debit", jcc[2025-02-01]) -> -8980 | L16: =SUMIF(jcc[Movement], "Credit", jcc[2025-03-01]) - SUMIF(jcc[Movement], "Debit", jcc[2025-03-01]) -> -8062.2725 | M16: =SUMIF(jcc[Movement], "Credit", jcc[2025-04-01]) - SUMIF(jcc[Movement], "Debit", jcc[2025-04-01]) -> -7128.3701 | N16: =SUMIF(jcc[Movement], "Credit", jcc[2025-05-01]) - SUMIF(jcc[Movement], "Debit", jcc[2025-05-01]) -> -6178.0076 | O16: =SUMIF(jcc[Movement], "Credit", jcc[2025-06-01]) - SUMIF(jcc[Movement], "Debit", jcc[2025-06-01]) -> -5210.895 | P16: =SUMIF(jcc[Movement], "Credit", jcc[2025-07-01]) - SUMIF(jcc[Movement], "Debit", jcc[2025-07-01]) -> -4226.737 | Q16: =SUMIF(jcc[Movement], "Credit", jcc[2025-08-01]) - SUMIF(jcc[Movement], "Debit", jcc[2025-08-01]) -> -3225.2332 | R16: =SUMIF(jcc[Movement], "Credit", jcc[2025-09-01]) - SUMIF(jcc[Movement], "Debit", jcc[2025-09-01]) -> -2206.078 | S16: =SUMIF(jcc[Movement], "Credit", jcc[2025-10-01]) - SUMIF(jcc[Movement], "Debit", jcc[2025-10-01]) -> -1168.9601 | T16: =SUMIF(jcc[Movement], "Credit", jcc[2025-11-01]) - SUMIF(jcc[Movement], "Debit", jcc[2025-11-01]) -> -113.563 | U16: =SUMIF(jcc[Movement], "Credit", jcc[2025-12-01]) - SUMIF(jcc[Movement], "Debit", jcc[2025-12-01]) -> 960.43545
A17: Debit Total | B17: Jeanre Credit Card | K17: =SUMIF(jcc[Movement], "Debit", jcc[2025-02-01]) -> 824 | L17: =SUMIF(jcc[Movement], "Debit", jcc[2025-03-01]) -> 982.2725 | M17: =SUMIF(jcc[Movement], "Debit", jcc[2025-04-01]) -> 966.09755 | N17: =SUMIF(jcc[Movement], "Debit", jcc[2025-05-01]) -> 949.63752 | O17: =SUMIF(jcc[Movement], "Debit", jcc[2025-06-01]) -> 932.88738 | P17: =SUMIF(jcc[Movement], "Debit", jcc[2025-07-01]) -> 915.84202 | Q17: =SUMIF(jcc[Movement], "Debit", jcc[2025-08-01]) -> 898.49624 | R17: =SUMIF(jcc[Movement], "Debit", jcc[2025-09-01]) -> 880.84474 | S17: =SUMIF(jcc[Movement], "Debit", jcc[2025-10-01]) -> 862.88212 | T17: =SUMIF(jcc[Movement], "Debit", jcc[2025-11-01]) -> 844.60292 | U17: =SUMIF(jcc[Movement], "Debit", jcc[2025-12-01]) -> 826.00155

Sheet Home Loan
A1: Movement | B1: Account Secondary | C1: 2024-05-01 | D1: 2024-06-01 | E1: 2024-07-01 | F1: 2024-08-01 | G1: 2024-09-01 | H1: 2024-10-01 | I1: 2024-11-01 | J1: 2024-12-01 | K1: 2025-01-01 | L1: 2025-02-01 | M1: 2025-03-01 | N1: 2025-04-01 | O1: 2025-05-01 | P1: 2025-06-01 | Q1: 2025-07-01 | R1: 2025-08-01 | S1: 2025-09-01 | T1: 2025-10-01 | U1: 2025-11-01 | V1: 2025-12-01 | W1: 2026-01-01 | X1: 2026-02-01 | Y1: 2026-03-01 | Z1: 2026-04-01 | AA1: 2026-05-01 | AB1: 2026-06-01 | AC1: 2026-07-01 | AD1: 2026-08-01 | AE1: 2026-09-01 | AF1: 2026-10-01 | AG1: 2026-11-01 | AH1: 2026-12-01
A2: Credit | B2: Jeanre Transactional | E2: 8140 | F2: 8140 | G2: 8140 | H2: 8140 | I2: 8140 | J2: 8140 | K2: 8140 | L2: 8140 | M2: 8140 | N2: 8140 | O2: 8140 | P2: 8140 | Q2: 8140 | R2: 8140 | S2: 8140 | T2: 8140 | U2: 8140 | V2: 8140 | W2: 8140 | X2: 8140 | Y2: 8140 | Z2: 8140 | AA2: 8140 | AB2: 8140 | AC2: 8140 | AD2: 8140 | AE2: 8140 | AF2: 8140 | AG2: 8140 | AH2: 8140
A3: Debit | B3: Budget Retained Balance | E3: 716601
A4: Subtotal | B4: Home Loan | C4: =SUMIF(Table3289[[Movement]:[Movement]],"Credit", Table3289[2024-05-01])-SUMIF(Table3289[[Movement]:[Movement]],"Debit", Table3289[2024-05-01]) -> 0 | D4: =SUMIF(Table3289[[Movement]:[Movement]],"Credit", Table3289[2024-06-01])-SUMIF(Table3289[[Movement]:[Movement]],"Debit", Table3289[2024-06-01]) -> 0 | E4: =SUMIF(Table3289[[Movement]:[Movement]],"Credit", Table3289[2024-07-01])-SUMIF(Table3289[[Movement]:[Movement]],"Debit", Table3289[2024-07-01]) -> -708461 | F4: =SUMIF(Table3289[[Movement]:[Movement]],"Credit", Table3289[2024-08-01])-SUMIF(Table3289[[Movement]:[Movement]],"Debit", Table3289[2024-08-01]) -> 8140 | G4: =SUMIF(Table3289[[Movement]:[Movement]],"Credit", Table3289[2024-09-01])-SUMIF(Table3289[[Movement]:[Movement]],"Debit", Table3289[2024-09-01]) -> 8140 | H4: =SUMIF(Table3289[[Movement]:[Movement]],"Credit", Table3289[2024-10-01])-SUMIF(Table3289[[Movement]:[Movement]],"Debit", Table3289[2024-10-01]) -> 8140 | I4: =SUMIF(Table3289[[Movement]:[Movement]],"Credit", Table3289[2024-11-01])-SUMIF(Table3289[[Movement]:[Movement]],"Debit", Table3289[2024-11-01]) -> 8140 | J4: =SUMIF(Table3289[[Movement]:[Movement]],"Credit", Table3289[2024-12-01])-SUMIF(Table3289[[Movement]:[Movement]],"Debit", Table3289[2024-12-01]) -> 8140 | K4: =SUMIF(Table3289[[Movement]:[Movement]],"Credit", Table3289[2025-01-01])-SUMIF(Table3289[[Movement]:[Movement]],"Debit", Table3289[2025-01-01]) -> 8140 | L4: =SUMIF(Table3289[[Movement]:[Movement]],"Credit", Table3289[2025-02-01])-SUMIF(Table3289[[Movement]:[Movement]],"Debit", Table3289[2025-02-01]) -> 8140 | M4: =SUMIF(Table3289[[Movement]:[Movement]],"Credit", Table3289[2025-03-01])-SUMIF(Table3289[[Movement]:[Movement]],"Debit", Table3289[2025-03-01]) -> 8140 | N4: =SUMIF(Table3289[[Movement]:[Movement]],"Credit", Table3289[2025-04-01])-SUMIF(Table3289[[Movement]:[Movement]],"Debit", Table3289[2025-04-01]) -> 8140 | O4: =SUMIF(Table3289[[Movement]:[Movement]],"Credit", Table3289[2025-05-01])-SUMIF(Table3289[[Movement]:[Movement]],"Debit", Table3289[2025-05-01]) -> 8140 | P4: =SUMIF(Table3289[[Movement]:[Movement]],"Credit", Table3289[2025-06-01])-SUMIF(Table3289[[Movement]:[Movement]],"Debit", Table3289[2025-06-01]) -> 8140 | Q4: =SUMIF(Table3289[[Movement]:[Movement]],"Credit", Table3289[2025-07-01])-SUMIF(Table3289[[Movement]:[Movement]],"Debit", Table3289[2025-07-01]) -> 8140 | R4: =SUMIF(Table3289[[Movement]:[Movement]],"Credit", Table3289[2025-08-01])-SUMIF(Table3289[[Movement]:[Movement]],"Debit", Table3289[2025-08-01]) -> 8140 | S4: =SUMIF(Table3289[[Movement]:[Movement]],"Credit", Table3289[2025-09-01])-SUMIF(Table3289[[Movement]:[Movement]],"Debit", Table3289[2025-09-01]) -> 8140 | T4: =SUMIF(Table3289[[Movement]:[Movement]],"Credit", Table3289[2025-10-01])-SUMIF(Table3289[[Movement]:[Movement]],"Debit", Table3289[2025-10-01]) -> 8140 | U4: =SUMIF(Table3289[[Movement]:[Movement]],"Credit", Table3289[2025-11-01])-SUMIF(Table3289[[Movement]:[Movement]],"Debit", Table3289[2025-11-01]) -> 8140 | V4: =SUMIF(Table3289[[Movement]:[Movement]],"Credit", Table3289[2025-12-01])-SUMIF(Table3289[[Movement]:[Movement]],"Debit", Table3289[2025-12-01]) -> 8140 | W4: =SUMIF(Table3289[[Movement]:[Movement]],"Credit", Table3289[2026-01-01])-SUMIF(Table3289[[Movement]:[Movement]],"Debit", Table3289[2026-01-01]) -> 8140 | X4: =SUMIF(Table3289[[Movement]:[Movement]],"Credit", Table3289[2026-02-01])-SUMIF(Table3289[[Movement]:[Movement]],"Debit", Table3289[2026-02-01]) -> 8140 | Y4: =SUMIF(Table3289[[Movement]:[Movement]],"Credit", Table3289[2026-03-01])-SUMIF(Table3289[[Movement]:[Movement]],"Debit", Table3289[2026-03-01]) -> 8140 | Z4: =SUMIF(Table3289[[Movement]:[Movement]],"Credit", Table3289[2026-04-01])-SUMIF(Table3289[[Movement]:[Movement]],"Debit", Table3289[2026-04-01]) -> 8140 | AA4: =SUMIF(Table3289[[Movement]:[Movement]],"Credit", Table3289[2026-05-01])-SUMIF(Table3289[[Movement]:[Movement]],"Debit", Table3289[2026-05-01]) -> 8140 | AB4: =SUMIF(Table3289[[Movement]:[Movement]],"Credit", Table3289[2026-06-01])-SUMIF(Table3289[[Movement]:[Movement]],"Debit", Table3289[2026-06-01]) -> 8140 | AC4: =SUMIF(Table3289[[Movement]:[Movement]],"Credit", Table3289[2026-07-01])-SUMIF(Table3289[[Movement]:[Movement]],"Debit", Table3289[2026-07-01]) -> 8140 | AD4: =SUMIF(Table3289[[Movement]:[Movement]],"Credit", Table3289[2026-08-01])-SUMIF(Table3289[[Movement]:[Movement]],"Debit", Table3289[2026-08-01]) -> 8140 | AE4: =SUMIF(Table3289[[Movement]:[Movement]],"Credit", Table3289[2026-09-01])-SUMIF(Table3289[[Movement]:[Movement]],"Debit", Table3289[2026-09-01]) -> 8140 | AF4: =SUMIF(Table3289[[Movement]:[Movement]],"Credit", Table3289[2026-10-01])-SUMIF(Table3289[[Movement]:[Movement]],"Debit", Table3289[2026-10-01]) -> 8140 | AG4: =SUMIF(Table3289[[Movement]:[Movement]],"Credit", Table3289[2026-11-01])-SUMIF(Table3289[[Movement]:[Movement]],"Debit", Table3289[2026-11-01]) -> 8140 | AH4: =SUMIF(Table3289[[Movement]:[Movement]],"Credit", Table3289[2026-12-01])-SUMIF(Table3289[[Movement]:[Movement]],"Debit", Table3289[2026-12-01]) -> 8140

Sheet Jodine U
A1: Movement | B1: Account Secondary | C1: 2024-05-01 | D1: 2024-06-01 | E1: 2024-07-01 | F1: 2024-08-01 | G1: 2024-09-01 | H1: 2024-10-01 | I1: 2024-11-01 | J1: 2024-12-01 | K1: 2025-01-01 | L1: 2025-02-01 | M1: 2025-03-01 | N1: 2025-04-01 | O1: 2025-05-01 | P1: 2025-06-01 | Q1: 2025-07-01 | R1: 2025-08-01 | S1: 2025-09-01 | T1: 2025-10-01 | U1: 2025-11-01 | V1: 2025-12-01 | W1: 2026-01-01 | X1: 2026-02-01 | Y1: 2026-03-01 | Z1: 2026-04-01 | AA1: 2026-05-01 | AB1: 2026-06-01 | AC1: 2026-07-01 | AD1: 2026-08-01 | AE1: 2026-09-01 | AF1: 2026-10-01 | AG1: 2026-11-01 | AH1: 2026-12-01
A2: Credit | B2: Jodine Transactional | C2: 1000 | D2: 1000 | E2: 750 | F2: 250 | G2: 750 | H2: 1000 | I2: 750 | J2: 750 | K2: 1000 | L2: 1000 | M2: 1000 | N2: 1000 | O2: 1000 | P2: 1000 | Q2: 1000 | R2: 1000 | S2: 1000 | T2: 1000 | U2: 1000 | V2: 1000 | W2: 1000 | X2: 1000 | Y2: 1000 | Z2: 1000 | AA2: 1000 | AB2: 1000 | AC2: 1000 | AD2: 1000 | AE2: 1000 | AF2: 1000
A3: Credit | B3: Retained Balance | H3: 3495
A4: Credit | B4: Jeanre Transactional | C4: 1000 | D4: 1000 | G4: 500 | H4: 1000 | I4: 1000 | J4: 1000 | K4: 5000 | L4: 5000 | M4: 5000 | N4: 5000 | O4: 5000 | P4: 5000 | Q4: 6000 | R4: 6000 | S4: 6000 | T4: 6000 | U4: 6000 | V4: 6000 | W4: 6000 | X4: 6000 | Y4: 6000 | Z4: 6000 | AA4: 6000 | AB4: 6000 | AC4: 6000 | AD4: 6000 | AE4: 6000 | AF4: 6000
A5: Debit | B5: CTU | C5: 10800 | D5: 5400 | E5: 5400 | F5: 5400 | G5: 5400 | H5: 5400 | K5: 5500 | L5: 5500 | M5: 5500 | N5: 5500 | O5: 5500 | P5: 5500 | Q5: 5500 | R5: 5500 | S5: 5500 | T5: 5500 | W5: 5600 | X5: 5600 | Y5: 5600 | Z5: 5600 | AA5: 5600 | AB5: 5600 | AC5: 5600 | AD5: 5600 | AE5: 5600 | AF5: 5600
A6: Debit | B6: Stationary | C6: 0
A7: Debit | B7: Jodine Deneysville visit | C7: 500
A8: Debit | B8: CTU Deposit | K8: 22000 | W8: 23000
A9: Subtotal | B9: Jodine U | C9: =SUMIF(Table328[[Movement]:[Movement]],"Credit", Table328[2024-05-01])-SUMIF(Table328[[Movement]:[Movement]],"Debit", Table328[2024-05-01]) -> -9300 | D9: =SUMIF(Table328[[Movement]:[Movement]],"Credit", Table328[2024-06-01])-SUMIF(Table328[[Movement]:[Movement]],"Debit", Table328[2024-06-01]) -> -3400 | E9: =SUMIF(Table328[[Movement]:[Movement]],"Credit", Table328[2024-07-01])-SUMIF(Table328[[Movement]:[Movement]],"Debit", Table328[2024-07-01]) -> -4650 | F9: =SUMIF(Table328[[Movement]:[Movement]],"Credit", Table328[2024-08-01])-SUMIF(Table328[[Movement]:[Movement]],"Debit", Table328[2024-08-01]) -> -5150 | G9: =SUMIF(Table328[[Movement]:[Movement]],"Credit", Table328[2024-09-01])-SUMIF(Table328[[Movement]:[Movement]],"Debit", Table328[2024-09-01]) -> -4150 | H9: =SUMIF(Table328[[Movement]:[Movement]],"Credit", Table328[2024-10-01])-SUMIF(Table328[[Movement]:[Movement]],"Debit", Table328[2024-10-01]) -> 95 | I9: =SUMIF(Table328[[Movement]:[Movement]],"Credit", Table328[2024-11-01])-SUMIF(Table328[[Movement]:[Movement]],"Debit", Table328[2024-11-01]) -> 1750 | J9: =SUMIF(Table328[[Movement]:[Movement]],"Credit", Table328[2024-12-01])-SUMIF(Table328[[Movement]:[Movement]],"Debit", Table328[2024-12-01]) -> 1750 | K9: =SUMIF(Table328[[Movement]:[Movement]],"Credit", Table328[2025-01-01])-SUMIF(Table328[[Movement]:[Movement]],"Debit", Table328[2025-01-01]) -> -21500 | L9: =SUMIF(Table328[[Movement]:[Movement]],"Credit", Table328[2025-02-01])-SUMIF(Table328[[Movement]:[Movement]],"Debit", Table328[2025-02-01]) -> 500 | M9: =SUMIF(Table328[[Movement]:[Movement]],"Credit", Table328[2025-03-01])-SUMIF(Table328[[Movement]:[Movement]],"Debit", Table328[2025-03-01]) -> 500 | N9: =SUMIF(Table328[[Movement]:[Movement]],"Credit", Table328[2025-04-01])-SUMIF(Table328[[Movement]:[Movement]],"Debit", Table328[2025-04-01]) -> 500 | O9: =SUMIF(Table328[[Movement]:[Movement]],"Credit", Table328[2025-05-01])-SUMIF(Table328[[Movement]:[Movement]],"Debit", Table328[2025-05-01]) -> 500 | P9: =SUMIF(Table328[[Movement]:[Movement]],"Credit", Table328[2025-06-01])-SUMIF(Table328[[Movement]:[Movement]],"Debit", Table328[2025-06-01]) -> 500 | Q9: =SUMIF(Table328[[Movement]:[Movement]],"Credit", Table328[2025-07-01])-SUMIF(Table328[[Movement]:[Movement]],"Debit", Table328[2025-07-01]) -> 1500 | R9: =SUMIF(Table328[[Movement]:[Movement]],"Credit", Table328[2025-08-01])-SUMIF(Table328[[Movement]:[Movement]],"Debit", Table328[2025-08-01]) -> 1500 | S9: =SUMIF(Table328[[Movement]:[Movement]],"Credit", Table328[2025-09-01])-SUMIF(Table328[[Movement]:[Movement]],"Debit", Table328[2025-09-01]) -> 1500 | T9: =SUMIF(Table328[[Movement]:[Movement]],"Credit", Table328[2025-10-01])-SUMIF(Table328[[Movement]:[Movement]],"Debit", Table328[2025-10-01]) -> 1500 | U9: =SUMIF(Table328[[Movement]:[Movement]],"Credit", Table328[2025-11-01])-SUMIF(Table328[[Movement]:[Movement]],"Debit", Table328[2025-11-01]) -> 7000 | V9: =SUMIF(Table328[[Movement]:[Movement]],"Credit", Table328[2025-12-01])-SUMIF(Table328[[Movement]:[Movement]],"Debit", Table328[2025-12-01]) -> 7000 | W9: =SUMIF(Table328[[Movement]:[Movement]],"Credit", Table328[2026-01-01])-SUMIF(Table328[[Movement]:[Movement]],"Debit", Table328[2026-01-01]) -> -21600 | X9: =SUMIF(Table328[[Movement]:[Movement]],"Credit", Table328[2026-02-01])-SUMIF(Table328[[Movement]:[Movement]],"Debit", Table328[2026-02-01]) -> 1400 | Y9: =SUMIF(Table328[[Movement]:[Movement]],"Credit", Table328[2026-03-01])-SUMIF(Table328[[Movement]:[Movement]],"Debit", Table328[2026-03-01]) -> 1400 | Z9: =SUMIF(Table328[[Movement]:[Movement]],"Credit", Table328[2026-04-01])-SUMIF(Table328[[Movement]:[Movement]],"Debit", Table328[2026-04-01]) -> 1400 | AA9: =SUMIF(Table328[[Movement]:[Movement]],"Credit", Table328[2026-05-01])-SUMIF(Table328[[Movement]:[Movement]],"Debit", Table328[2026-05-01]) -> 1400 | AB9: =SUMIF(Table328[[Movement]:[Movement]],"Credit", Table328[2026-06-01])-SUMIF(Table328[[Movement]:[Movement]],"Debit", Table328[2026-06-01]) -> 1400 | AC9: =SUMIF(Table328[[Movement]:[Movement]],"Credit", Table328[2026-07-01])-SUMIF(Table328[[Movement]:[Movement]],"Debit", Table328[2026-07-01]) -> 1400 | AD9: =SUMIF(Table328[[Movement]:[Movement]],"Credit", Table328[2026-08-01])-SUMIF(Table328[[Movement]:[Movement]],"Debit", Table328[2026-08-01]) -> 1400 | AE9: =SUMIF(Table328[[Movement]:[Movement]],"Credit", Table328[2026-09-01])-SUMIF(Table328[[Movement]:[Movement]],"Debit", Table328[2026-09-01]) -> 1400 | AF9: =SUMIF(Table328[[Movement]:[Movement]],"Credit", Table328[2026-10-01])-SUMIF(Table328[[Movement]:[Movement]],"Debit", Table328[2026-10-01]) -> 1400 | AG9: =SUMIF(Table328[[Movement]:[Movement]],"Credit", Table328[2026-11-01])-SUMIF(Table328[[Movement]:[Movement]],"Debit", Table328[2026-11-01]) -> 0 | AH9: =SUMIF(Table328[[Movement]:[Movement]],"Credit", Table328[2026-12-01])-SUMIF(Table328[[Movement]:[Movement]],"Debit", Table328[2026-12-01]) -> 0

Sheet Emergency
A1: Movement | B1: Account Secondary | C1: 2024-05-01 | D1: 2024-06-01 | E1: 2024-07-01 | F1: 2024-08-01 | G1: 2024-09-01 | H1: 2024-10-01 | I1: 2024-11-01 | J1: 2024-12-01
A2: Credit | B2: Jeanre Transactional | C2: 200 | D2: 200 | E2: 200 | F2: 200 | G2: 200 | H2: 200 | I2: 200 | J2: 200
A3: Debit | B3: Other | C3: 0 | D3: R - | E3: R - | F3: R - | G3: R - | H3: R - | I3: R - | J3: R -
A4: Subtotal | B4: Emergency | C4: =SUMIF(Table5[[Movement]:[Movement]],"Credit", Table5[2024-05-01])-SUMIF(Table5[[Movement]:[Movement]],"Debit", Table5[2024-05-01]) -> 200 | D4: =SUMIF(Table5[[Movement]:[Movement]],"Credit", Table5[2024-06-01])-SUMIF(Table5[[Movement]:[Movement]],"Debit", Table5[2024-06-01]) -> 200 | E4: =SUMIF(Table5[[Movement]:[Movement]],"Credit", Table5[2024-07-01])-SUMIF(Table5[[Movement]:[Movement]],"Debit", Table5[2024-07-01]) -> 200 | F4: =SUMIF(Table5[[Movement]:[Movement]],"Credit", Table5[2024-08-01])-SUMIF(Table5[[Movement]:[Movement]],"Debit", Table5[2024-08-01]) -> 200 | G4: =SUMIF(Table5[[Movement]:[Movement]],"Credit", Table5[2024-09-01])-SUMIF(Table5[[Movement]:[Movement]],"Debit", Table5[2024-09-01]) -> 200 | H4: =SUMIF(Table5[[Movement]:[Movement]],"Credit", Table5[2024-10-01])-SUMIF(Table5[[Movement]:[Movement]],"Debit", Table5[2024-10-01]) -> 200 | I4: =SUMIF(Table5[[Movement]:[Movement]],"Credit", Table5[2024-11-01])-SUMIF(Table5[[Movement]:[Movement]],"Debit", Table5[2024-11-01]) -> 200 | J4: =SUMIF(Table5[[Movement]:[Movement]],"Credit", Table5[2024-12-01])-SUMIF(Table5[[Movement]:[Movement]],"Debit", Table5[2024-12-01]) -> 200

Sheet Personal Wealth
A1: Movement | B1: Account Secondary | C1: 2024-05-01 | D1: 2024-06-01 | E1: 2024-07-01 | F1: 2024-08-01 | G1: 2024-09-01 | H1: 2024-10-01 | I1: 2024-11-01 | J1: 2024-12-01
A2: Credit | B2: Jeanre Transactional | D2: 500 | E2: 0 | F2: 0 | G2: 0 | H2: 0 | I2: 0 | J2: 0
A3: Debit | B3: Daniel Bachelors | D3: 1000 | E3: 1000
A4: Debit | B4: Suzuki Maintenance | E4: 4000
A5: Debit | B5: Daniel Wedding | G5: 500
A6: Debit | B6: Bernice Eyes | H6: 5000
A7: Debit | B7: Clothing | E7: 3000
A8: Debit | B8: Ian Wedding | F8: 500
A9: Subtotal | B9: Personal Wealth | C9: =SUMIF(Table32810[[Movement]:[Movement]],"Credit", Table32810[2024-05-01])-SUMIF(Table32810[[Movement]:[Movement]],"Debit", Table32810[2024-05-01]) -> 0 | D9: =SUMIF(Table32810[[Movement]:[Movement]],"Credit", Table32810[2024-06-01])-SUMIF(Table32810[[Movement]:[Movement]],"Debit", Table32810[2024-06-01]) -> -500 | E9: =SUMIF(Table32810[[Movement]:[Movement]],"Credit", Table32810[2024-07-01])-SUMIF(Table32810[[Movement]:[Movement]],"Debit", Table32810[2024-07-01]) -> -8000 | F9: =SUMIF(Table32810[[Movement]:[Movement]],"Credit", Table32810[2024-08-01])-SUMIF(Table32810[[Movement]:[Movement]],"Debit", Table32810[2024-08-01]) -> -500 | G9: =SUMIF(Table32810[[Movement]:[Movement]],"Credit", Table32810[2024-09-01])-SUMIF(Table32810[[Movement]:[Movement]],"Debit", Table32810[2024-09-01]) -> -500 | H9: =SUMIF(Table32810[[Movement]:[Movement]],"Credit", Table32810[2024-10-01])-SUMIF(Table32810[[Movement]:[Movement]],"Debit", Table32810[2024-10-01]) -> -5000 | I9: =SUMIF(Table32810[[Movement]:[Movement]],"Credit", Table32810[2024-11-01])-SUMIF(Table32810[[Movement]:[Movement]],"Debit", Table32810[2024-11-01]) -> 0 | J9: =SUMIF(Table32810[[Movement]:[Movement]],"Credit", Table32810[2024-12-01])-SUMIF(Table32810[[Movement]:[Movement]],"Debit", Table32810[2024-12-01]) -> 0

Sheet Dec 2025 calcs
A1: things to pay | B1: amount to pay | C1: no-choice
G2: 17112 | K2: cash
A3: Bernice Transactional | B3: 8000 | C3: 8000 | K3: 7690
A4: Bicycle Claims | B4: 1169 | C4: 1169 | G4: 1169 | J4: jodine | K4: -400
A5: Emergency | B5: -200 | C5: -200 | J5: save | K5: -1000
A6: Home Insurance | B6: -610 | C6: 1220 | G6: -1220 | J6: Jan Account | K6: -3000
A7: Home Loan | B7: -8140 | C7: -8140 | G7: -8020 | J7: jan spend | K7: 1290
A8: Internet | B8: -1000 | C8: -1000 | G8: -1000 | J8: feb | K8: 1000
A9: Jodine U | B9: -500 | J9: march | K9: 1000
A10: Life Insurance | B10: -440 | C10: -440 | G10: -440
A11: Medical Aid | B11: -5600 | C11: -5600 | G11: -5600
A12: Municipal Account | B12: -3700 | C12: -3700 | G12: -3400 | H12: done
A13: Netstar | B13: -170 | C13: -170 | G13: -170
A14: Personal Wealth | B14: -3000
A15: Shortfall Insurance | B15: -117 | C15: -117 | G15: -117
A16: Vehicle Insurance | B16: -988 | C16: -988 | G16: -988
A17: Vehicle Licenses | B17: -500 | C17: -500
A18: previous month insurance | C18: 610 | G18: 610
B19: =SUM(B3:B17) -> -15796 | C19: =SUM(C3:C18) -> -9856 | G19: =SUM(G2:G18) -> -2064

Sheet Jeanre Credit Card-old
A1: Movement | B1: Account Secondary | C1: 2024-05-01 | D1: 2024-06-01 | E1: 2024-07-01 | F1: 2024-08-01 | G1: 2024-09-01 | H1: 2024-10-01 | I1: 2024-11-01 | J1: 2024-12-01
A2: Credit | B2: Jeanre Transactional | C2: 500 | D2: 1500 | E2: 250 | F2: 500 | G2: 500 | H2: 600 | I2: 500 | J2: 500
A3: Debit | B3: Netflix | C3: 0 | D3: 200 | E3: 200 | F3: 200 | G3: 200 | H3: 200 | I3: 200 | J3: 200
A4: Debit | B4: Gaming | G4: 110 | H4: 110 | I4: 110 | J4: 110
A5: Debit | B5: Apple One | C5: 0 | D5: 230 | E5: 230 | F5: 230 | G5: 230 | H5: 230 | I5: 230 | J5: 230
A6: Subtotal | B6: Jeanre Credit Card | C6: =SUMIF(Table323[[Movement]:[Movement]],"Credit", Table323[2024-05-01])-SUMIF(Table323[[Movement]:[Movement]],"Debit", Table323[2024-05-01]) -> 500 | D6: =SUMIF(Table323[[Movement]:[Movement]],"Credit", Table323[2024-06-01])-SUMIF(Table323[[Movement]:[Movement]],"Debit", Table323[2024-06-01]) -> 1070 | E6: =SUMIF(Table323[[Movement]:[Movement]],"Credit", Table323[2024-07-01])-SUMIF(Table323[[Movement]:[Movement]],"Debit", Table323[2024-07-01]) -> -180 | F6: =SUMIF(Table323[[Movement]:[Movement]],"Credit", Table323[2024-08-01])-SUMIF(Table323[[Movement]:[Movement]],"Debit", Table323[2024-08-01]) -> 70 | G6: =SUMIF(Table323[[Movement]:[Movement]],"Credit", Table323[2024-09-01])-SUMIF(Table323[[Movement]:[Movement]],"Debit", Table323[2024-09-01]) -> -40 | H6: =SUMIF(Table323[[Movement]:[Movement]],"Credit", Table323[2024-10-01])-SUMIF(Table323[[Movement]:[Movement]],"Debit", Table323[2024-10-01]) -> 60 | I6: =SUMIF(Table323[[Movement]:[Movement]],"Credit", Table323[2024-11-01])-SUMIF(Table323[[Movement]:[Movement]],"Debit", Table323[2024-11-01]) -> -40 | J6: =SUMIF(Table323[[Movement]:[Movement]],"Credit", Table323[2024-12-01])-SUMIF(Table323[[Movement]:[Movement]],"Debit", Table323[2024-12-01]) -> -40

Sheet Bernice Credit Card-old
A1: Movement | B1: Account Secondary | C1: 2024-05-01 | D1: 2024-06-01 | E1: 2024-07-01 | F1: 2024-08-01 | G1: 2024-09-01 | H1: 2024-10-01 | I1: 2024-11-01 | J1: 2024-12-01 | K1: 2025-02-01 | L1: 2025-03-01 | M1: 2025-04-01 | N1: 2025-05-01 | O1: 2025-06-01 | P1: 2025-07-01 | Q1: 2025-08-01 | R1: 2025-09-01 | S1: 2025-10-01 | T1: 2025-11-01 | U1: 2025-12-01
A2: Credit | B2: Bernice Transactional | C2: 2000 | D2: 0 | E2: 500 | F2: 500 | G2: 500 | H2: 500 | I2: 500 | J2: 500 | K2: 900 | L2: 900 | M2: 900 | N2: 900 | O2: 900 | P2: 900 | Q2: 900 | R2: 800 | S2: 800 | T2: 800 | U2: 800
A3: Credit | B3: Retained Balance | K3: -30 | L3: =K7 -> -4130 | M3: =L7 -> -3230 | N3: =M7 -> -2330 | O3: =N7 -> -1430 | P3: =O7 -> -530 | Q3: =P7 -> 370 | R3: =Q7 -> -2230 | S3: =R7 -> -1430 | ... U3: =T7 -> 170
A4: Debit | B4: Bulk Meat | E4: 3550 | K4: 3500 | Q4: 3500
A5: Debit | B5: Geely Parts | K5: 1500
A6: Debit | B6: Other | C6: 0 | D6: 0 | E6: 0 | F6: 0 | G6: 0 | H6: 0 | I6: 0 | J6: 0
A7: Subtotal | B7: Bernice Credit Card | C7: =SUMIF(bcc[[Movement]:[Movement]],"Credit", bcc[2024-05-01])-SUMIF(bcc[[Movement]:[Movement]],"Debit",bcc[2024-05-01]) -> 2000 | D7: =SUMIF(bcc[[Movement]:[Movement]],"Credit", bcc[2024-06-01])-SUMIF(bcc[[Movement]:[Movement]],"Debit",bcc[2024-06-01]) -> 0 | E7: =SUMIF(bcc[[Movement]:[Movement]],"Credit", bcc[2024-07-01])-SUMIF(bcc[[Movement]:[Movement]],"Debit",bcc[2024-07-01]) -> -3050 | F7: =SUMIF(bcc[[Movement]:[Movement]],"Credit", bcc[2024-08-01])-SUMIF(bcc[[Movement]:[Movement]],"Debit",bcc[2024-08-01]) -> 500 | G7: =SUMIF(bcc[[Movement]:[Movement]],"Credit", bcc[2024-09-01])-SUMIF(bcc[[Movement]:[Movement]],"Debit",bcc[2024-09-01]) -> 500 | H7: =SUMIF(bcc[[Movement]:[Movement]],"Credit", bcc[2024-10-01])-SUMIF(bcc[[Movement]:[Movement]],"Debit",bcc[2024-10-01]) -> 500 | I7: =SUMIF(bcc[[Movement]:[Movement]],"Credit", bcc[2024-11-01])-SUMIF(bcc[[Movement]:[Movement]],"Debit",bcc[2024-11-01]) -> 500 | J7: =SUMIF(bcc[[Movement]:[Movement]],"Credit", bcc[2024-12-01])-SUMIF(bcc[[Movement]:[Movement]],"Debit",bcc[2024-12-01]) -> 500 | K7: =SUMIF(bcc[Movement], "Credit", bcc[2025-02-01]) - SUMIF(bcc[Movement], "Debit", bcc[2025-02-01]) -> -4130 | L7: =SUMIF(bcc[Movement], "Credit", bcc[2025-03-01]) - SUMIF(bcc[Movement], "Debit", bcc[2025-03-01]) -> -3230 | M7: =SUMIF(bcc[Movement], "Credit", bcc[2025-04-01]) - SUMIF(bcc[Movement], "Debit", bcc[2025-04-01]) -> -2330 | N7: =SUMIF(bcc[Movement], "Credit", bcc[2025-05-01]) - SUMIF(bcc[Movement], "Debit", bcc[2025-05-01]) -> -1430 | O7: =SUMIF(bcc[Movement], "Credit", bcc[2025-06-01]) - SUMIF(bcc[Movement], "Debit", bcc[2025-06-01]) -> -530 | P7: =SUMIF(bcc[Movement], "Credit", bcc[2025-07-01]) - SUMIF(bcc[Movement], "Debit", bcc[2025-07-01]) -> 370 | Q7: =SUMIF(bcc[Movement], "Credit", bcc[2025-08-01]) - SUMIF(bcc[Movement], "Debit", bcc[2025-08-01]) -> -2230 | R7: =SUMIF(bcc[Movement], "Credit", bcc[2025-09-01]) - SUMIF(bcc[Movement], "Debit", bcc[2025-09-01]) -> -1430 | S7: =SUMIF(bcc[Movement], "Credit", bcc[2025-10-01]) - SUMIF(bcc[Movement], "Debit", bcc[2025-10-01]) -> -630 | T7: =SUMIF(bcc[Movement], "Credit", bcc[2025-11-01]) - SUMIF(bcc[Movement], "Debit", bcc[2025-11-01]) -> 170 | U7: =SUMIF(bcc[Movement], "Credit", bcc[2025-12-01]) - SUMIF(bcc[Movement], "Debit", bcc[2025-12-01]) -> 970
N13: 8000
N14: 30
N15: 1500
N16: 3500
M17: left | N17: =N13-SUM(N14:N16) -> 2970
M18: debt | N18: =SUM(N14:N16) -> 5030
M19: divide by 700 to get months | N19: =N18/700 -> 7.1857143
M20: divide by 900 to get months | N20: =N18/900 -> 5.5888889
