Workbook

Sheet Jeanre Transactional
A1: Movement | B1: Account Secondary | C1: 2024-05-01 | D1: 2024-06-01 | E1: 2024-07-01 | F1: 2024-08-01 | G1: 2024-09-01 | H1: 2024-10-01 | I1: 2024-11-01 | J1: 2024-12-01 | K1: 2025-01-01 | L1: 2025-02-01 | M1: 2025-03-01 | N1: 2025-04-01 | O1: 2025-05-01 | P1: 2025-06-01 | Q1: 2025-07-01 | R1: 2025-08-01 | S1: 2025-09-01 | T1: 2025-10-01 | U1: 2025-11-01 | V1: 2025-12-01
A2: Credit | B2: Salary | C2: 27000 | D2: 27000 | E2: 21600 | F2: 21600 | G2: 21600 | H2: 21600 | I2: 21600 | J2: 25100 | K2: 25100 | L2: 21600 | M2: 23100 | N2: 24600 | O2: 24600 | P2: 24600 | Q2: 24600 | R2: 24600 | S2: 24600 | T2: 24600 | U2: 24600 | V2: 24600
A3: Credit | B3: Bicycle Claims | C3: 1325 | D3: 1325 | E3: 1325 | F3: 1325 | G3: 1325 | H3: 1000 | I3: 1000 | J3: 1169 | K3: 1169 | L3: 1169 | M3: 1169 | N3: 1669 | O3: 1169 | P3: 1349 | Q3: 1349 | R3: 1169 | S3: 3089 | T3: 1169 | U3: 1169 | V3: 1169
A4: Credit | B4: Jodine U | S4: 3825
A5: Credit | B5: Jodine Transactional | F5: 750 | G5: 1250 | I5: 250 | T5: 4010 | U5: 4010 | V5: 4010
A6: Credit | B6: Other | Q6: 300
A7: Credit | B7: Personal Wealth | H7: 0 | I7: 3500
A8: Credit | B8: Retained Balance | M8: 259 | N8: 137 | O8: 0 | P8: 1024 | Q8: 900 | R8: =jtrn[[#Totals],[2025-07-01]] -> 1367 | S8: 34 | T8: 125.21 | U8: =jtrn[[#Totals],[2025-10-01]] -> -2374.79 | V8: =jtrn[[#Totals],[2025-11-01]] -> -2009.79
A9: Credit | B9: Tax Refund | G9: 5700
A10: Credit | B10: Bernice Transactional | C10: 7700 | D10: 7700 | E10: 7000 | F10: 6800 | G10: 7000 | H10: 7300 | I10: 7750 | J10: 8000 | K10: 8000 | L10: 7700 | M10: 8000 | N10: 8000 | O10: 8000 | P10: 8000 | Q10: 8000 | R10: 8000 | S10: 7300 | T10: 7500 | U10: 7300 | V10: 7300
A11: Debit | B11: Jeanre Credit Card | C11: 500 | D11: 1500 | E11: 250 | F11: 500 | G11: 500 | H11: 1000 | I11: 750 | J11: 1000 | K11: 1000 | L11: 1000 | M11: 2000 | N11: 1700 | O11: 1000 | P11: 2000 | Q11: 1500 | R11: 2000 | S11: 2500 | T11: 1500 | U11: 2500 | V11: 2500
A12: Debit | B12: Home Loan | C12: 8140 | D12: 8140 | E12: 8140 | F12: 8140 | G12: 8140 | H12: 8140 | I12: 8140 | J12: 8140 | K12: 8140 | L12: 7910 | M12: 7795 | N12: 7795 | O12: 7795 | P12: 7795 | Q12: 7795 | R12: 7795 | S12: 7795 | T12: 7795 | U12: 7795 | V12: 7795
A13: Debit | B13: Vehicle Loan | C13: 3500 | D13: 3578 | E13: 3578 | F13: 3578 | G13: 3578 | H13: 3578 | I13: 3578 | J13: 3578 | K13: 3578 | L13: 3577 | M13: 3577 | N13: 3577 | O13: 3577 | P13: 3577 | Q13: 3577 | R13: 3577 | S13: 3577 | T13: 3577 | U13: 3577 | V13: 3577
A14: Debit | B14: Medical Aid | C14: 4530 | D14: 4530 | E14: 4530 | F14: 4530 | G14: 5600 | H14: 5600 | I14: 5600 | J14: 5600 | K14: 5600 | L14: 6305 | M14: 6305 | N14: 6305 | O14: 6305 | P14: 6305 | Q14: 6305 | S14: 6305 | T14: 12610 | U14: 6305 | V14: 6305
A15: Debit | B15: Netstar | C15: 110 | D15: 170 | E15: 170 | F15: 170 | G15: 170 | H15: 170 | I15: 170 | J15: 170 | K15: 170 | L15: 170 | M15: 170 | N15: 170 | O15: 170 | P15: 170 | Q15: 170 | R15: 170 | S15: 170 | T15: 170 | U15: 170 | V15: 170
A16: Debit | B16: Shortfall Insurance | C16: 117 | D16: 117 | E16: 117 | F16: 117 | G16: 117 | H16: 117 | I16: 117 | J16: 117 | K16: 117 | L16: 117 | M16: 117 | N16: 117 | O16: 117 | P16: 117 | Q16: 117 | R16: 117 | S16: 117 | T16: 117 | U16: 117 | V16: 117
A17: Debit | B17: Vehicle Insurance | C17: 1050 | D17: 988 | E17: 988 | F17: 988 | G17: 988 | H17: 988 | I17: 988 | J17: 988 | K17: 988 | L17: 988 | M17: 690 | N17: 690 | O17: 855 | P17: 690 | Q17: 690 | R17: 856 | S17: 690 | T17: 690 | U17: 690 | V17: 690
A18: Debit | B18: Home Insurance | C18: 1200 | D18: 560 | E18: 560 | F18: 560 | G18: 560 | H18: 560 | I18: 610 | J18: 610 | K18: 610 | L18: 610 | M18: 610 | N18: 610 | O18: 610 | P18: 610 | Q18: 610 | R18: 610 | S18: 610 | T18: 610 | U18: 610 | V18: 610
A19: Debit | B19: Life Insurance | C19: 440 | D19: 440 | E19: 440 | F19: 440 | G19: 440 | H19: 440 | I19: 440 | J19: 440 | K19: 440 | L19: 450 | M19: 450 | N19: 450 | O19: 450 | P19: 450 | Q19: 450 | R19: 450 | S19: 450 | T19: 450 | U19: 450 | V19: 450
A20: Debit | B20: Municipal Account | C20: 3500 | D20: 3500 | E20: 3500 | F20: 3500 | G20: 3500 | H20: 4000 | I20: 4000 | J20: 3700 | K20: 3700 | L20: 3000 | M20: 3200 | N20: 4726 | O20: 3260 | P20: 4100 | Q20: 0 | R20: 3200 | S20: 3500 | T20: 3500 | U20: 3200 | V20: 3200
A21: Debit | B21: Internet | C21: 1000 | D21: 1000 | E21: 1000 | F21: 1000 | G21: 1000 | H21: 1000 | I21: 1000 | J21: 1000 | K21: 1000 | L21: 1000 | M21: 1000 | N21: 1000 | O21: 1000 | P21: 1000 | Q21: 1000 | R21: 1000 | S21: 1000 | T21: 1000 | U21: 1000 | V21: 1000
A22: Debit | B22: Fuel | C22: 1000 | D22: 1500 | E22: 250 | F22: 500 | G22: 900 | H22: 200 | I22: 150 | J22: 900 | K22: 900 | L22: 500 | M22: 500 | N22: 400 | O22: 400 | P22: 1000 | Q22: 550 | R22: 400 | S22: 400 | T22: 250 | U22: 400 | V22: 400
A23: Debit | B23: Running Costs | C23: 5000 | D23: 4300 | E23: 3000 | F23: 3500 | G23: 3200 | H23: 3000 | I23: 3500 | J23: 4000 | K23: 4000 | L23: 2600 | M23: 3700 | N23: 3400 | O23: 3500 | P23: 3700 | Q23: 5928 | R23: 3700 | S23: 3700 | T23: 2000 | U23: 3700 | V23: 3700
A24: Debit | B24: Administration | C24: 0 | D24: 0 | E24: 0 | F24: 0 | G24: 0 | H24: 0 | I24: 0 | J24: 0 | K24: 0
A25: Debit | B25: Jodine Transactional | C25: 500 | D25: 200 | F25: 0 | G25: 0 | H25: 0 | I25: 0 | J25: 0 | K25: 0
A26: Debit | B26: Jodine AIE | S26: 3825 | T26: 4010
A27: Debit | B27: Jodine U | C27: 1000 | D27: 1000 | E27: 0 | G27: 500 | H27: 1000 | I27: 500 | J27: 500 | K27: 500 | N27: 1500 | O27: 1500 | Q27: 500 | R27: 0 | S27: 0 | T27: 0 | U27: 0 | V27: 0
A28: Debit | B28: Emergency | C28: 200 | D28: 200 | E28: 200 | F28: 200 | G28: 200 | H28: 0 | I28: 200 | J28: 200 | K28: 200 | L28: 900 | M28: 400 | N28: 400 | O28: 400 | P28: 400 | Q28: 400 | R28: 400 | S28: 400 | U28: 400 | V28: 400
A29: Debit | B29: Jeanre Retirement | C29: 0 | D29: 0 | E29: 0 | F29: 0 | G29: 0 | H29: 0 | I29: 0 | J29: 0 | K29: 0
A30: Debit | B30: Vehicle Licenses | E30: 640 | F30: 0 | G30: 0 | H30: 0 | I30: 0 | J30: 500 | K30: 500 | L30: 432 | Q30: 750
A31: Debit | B31: Other | E31: 600 | F31: 600 | H31: 580 | Q31: 250
A32: Debit | B32: Accounts | I32: 2227 | Q32: 1090
A33: Debit | B33: Events | I33: 2065 | U33: 2000
A34: Debit | B34: Medical | M34: 900 | N34: 500 | O34: 500 | P34: 500 | Q34: 900 | R34: 900 | S34: 900 | U34: 900 | V34: 900
A35: Debit | B35: Tax | F35: 500 | G35: 500
A36: Debit | B36: Cell Phones | C36: 3100 | D36: 1700 | E36: 1820 | F36: 1820 | G36: 0 | H36: 0 | I36: 0 | J36: 0 | K36: 0
A37: Debit | B37: Jansie | C37: 600 | D37: 600 | E37: 0 | F37: 0 | G37: 0 | H37: 0 | I37: 0 | J37: 0 | K37: 0 | S37: 1700
A38: Debit | B38: H Smith | S38: 1432
A39: Debit | B39: Vape
A40: Debit | B40: Easy Equities | N40: 200 | O40: 200 | P40: 200 | Q40: 200 | R40: 200 | S40: 1000 | U40: 200 | V40: 200
...

Sheet Bernice Transactional
A1: Movement | B1: Account Secondary | C1: 2024-05-01 | D1: 2024-06-01 | E1: 2024-07-01 | F1: 2024-08-01 | G1: 2024-09-01 | H1: 2024-10-01 | I1: 2024-11-01 | J1: 2024-12-01 | K1: 2024-12-02 | L1: 2025-01-01 | M1: 2025-02-01 | N1: 2025-03-01 | O1: 2025-04-01 | P1: 2025-05-01 | Q1: 2025-06-01 | R1: 2025-07-01 | S1: 2025-08-01 | T1: 2025-09-01 | U1: 2025-10-01 | V1: 2025-11-01 | W1: 2025-12-01
A2: Credit | B2: Salary | C2: 11000 | D2: 11000 | E2: 8800 | F2: 8800 | G2: 8800 | H2: 8800 | I2: 8800 | J2: 11300 | K2: 11300 | M2: 8800 | N2: 9550 | O2: 10300 | P2: 10300 | Q2: 10300 | R2: 10300 | S2: 10300 | T2: 10300 | U2: 10300 | V2: 10300 | W2: 10300
A3: Credit | B3: Retained Balance | M3: 350 | N3: 726 | O3: 125 | P3: =O15 -> 84 | Q3: 30 | R3: 33 | S3: 34 | T3: =S15 -> 184 | U3: 172 | V3: =U15 -> 44 | W3: =V15 -> -6
A4: Debit | B4: Bernice Credit Card | C4: 2000 | D4: 2000 | E4: 500 | F4: 500 | G4: 500 | H4: 500 | I4: 700 | J4: 2200 | K4: 2200 | M4: 900 | N4: 1500 | O4: 2000 | P4: 2043 | Q4: 2000 | R4: 1900 | S4: 2000 | T4: 2000 | U4: 2000 | V4: 2000 | W4: 2000
A5: Debit | B5: Jeanre Transactional | C5: 7700 | D5: 7700 | E5: 7000 | F5: 6800 | G5: 7000 | H5: 7300 | I5: 7750 | J5: 8000 | K5: 8000 | M5: 7700 | N5: 8000 | O5: 8000 | P5: 8000 | Q5: 8000 | R5: 8000 | S5: 7300 | T5: 7300 | U5: 7500 | V5: 7500 | W5: 7500
A6: Debit | B6: Fees | M6: =SUMIF([1]!jtrn[Movement], "Credit", [1]!jtrn[2025-02-01]) - SUMIF([1]!jtrn[Movement], "Debit", [1]!jtrn[2025-02-01]) -> 10 | N6: 75 | O6: 75 | P6: 75 | Q6: 75 | R6: 110 | S6: 200 | T6: 200 | U6: 200 | V6: 200 | W6: 200
A7: Debit | B7: Geely Insurance | C7: 110 | D7: 110 | E7: 110 | F7: 110 | G7: 110 | H7: 110 | I7: 110 | J7: 110 | K7: 110
A8: Debit | B8: Medical | C8: 900 | D8: 900 | E8: 900 | F8: 900
A9: Debit | B9: Bernice Retirement | C9: 0 | D9: 0 | E9: 0 | F9: 0 | G9: 0 | H9: 0 | I9: 0 | J9: 0 | K9: 0
A10: Debit | B10: Bernice Personal Savings | C10: 0 | D10: 200 | E10: 200 | F10: 200 | G10: 200 | H10: 200 | I10: 200 | J10: 200 | K10: 200 | M10: 200 | N10: 250 | O10: 250 | P10: 300 | Q10: 200 | R10: 200 | S10: 150 | T10: 150 | U10: 150 | V10: 150 | W10: 150
A11: Debit | B11: Comic Con | H11: 607
A12: Debit | B12: Child | M12: =SUMIF([1]!jtrn[Movement], "Credit", [1]!jtrn[2025-02-01]) - SUMIF([1]!jtrn[Movement], "Debit", [1]!jtrn[2025-02-01]) -> 10 | N12: =SUMIF([1]!jtrn[Movement], "Credit", [1]!jtrn[2025-03-01]) - SUMIF([1]!jtrn[Movement], "Debit", [1]!jtrn[2025-03-01]) -> 614 | O12: =SUMIF([1]!jtrn[Movement], "Credit", [1]!jtrn[2025-04-01]) - SUMIF([1]!jtrn[Movement], "Debit", [1]!jtrn[2025-04-01]) -> 16 | P12: =SUMIF([1]!jtrn[Movement], "Credit", [1]!jtrn[2025-05-01]) - SUMIF([1]!jtrn[Movement], "Debit", [1]!jtrn[2025-05-01]) -> 530 | Q12: =SUMIF([1]!jtrn[Movement], "Credit", [1]!jtrn[2025-06-01]) - SUMIF([1]!jtrn[Movement], "Debit", [1]!jtrn[2025-06-01]) -> 1359 | R12: =SUMIF([1]!jtrn[Movement], "Credit", [1]!jtrn[2025-07-01]) - SUMIF([1]!jtrn[Movement], "Debit", [1]!jtrn[2025-07-01]) -> 135 | S12: 500 | T12: 500 | U12: 500 | V12: 500 | W12: 500
A13: Debit | B13: Other | M13: =SUMIF([1]!jtrn[Movement], "Credit", [1]!jtrn[2025-02-01]) - SUMIF([1]!jtrn[Movement], "Debit", [1]!jtrn[2025-02-01]) -> 10 | N13: 320 | U13: 78
A14: Debit | B14: Home and Vehicle Savings | C14: 0 | D14: 0 | E14: 0 | F14: 0 | G14: 0 | H14: 0 | I14: 0 | J14: 0 | K14: 0
A15: Subtotal | B15: Bernice Transactional | C15: =SUMIF(btrn[[Movement]:[Movement]],"Credit", btrn[2024-05-01])-SUMIF(btrn[[Movement]:[Movement]],"Debit",btrn[2024-05-01]) -> 290 | D15: =SUMIF(btrn[[Movement]:[Movement]],"Credit", btrn[2024-06-01])-SUMIF(btrn[[Movement]:[Movement]],"Debit",btrn[2024-06-01]) -> 90 | E15: =SUMIF(btrn[[Movement]:[Movement]],"Credit", btrn[2024-07-01])-SUMIF(btrn[[Movement]:[Movement]],"Debit",btrn[2024-07-01]) -> 90 | F15: =SUMIF(btrn[[Movement]:[Movement]],"Credit", btrn[2024-08-01])-SUMIF(btrn[[Movement]:[Movement]],"Debit",btrn[2024-08-01]) -> 290 | G15: =SUMIF(btrn[[Movement]:[Movement]],"Credit", btrn[2024-09-01])-SUMIF(btrn[[Movement]:[Movement]],"Debit",btrn[2024-09-01]) -> 990 | H15: =SUMIF(btrn[[Movement]:[Movement]],"Credit", btrn[2024-10-01])-SUMIF(btrn[[Movement]:[Movement]],"Debit",btrn[2024-10-01]) -> 83 | I15: =SUMIF(btrn[[Movement]:[Movement]],"Credit", btrn[2024-11-01])-SUMIF(btrn[[Movement]:[Movement]],"Debit",btrn[2024-11-01]) -> 40 | J15: =SUMIF(btrn[[Movement]:[Movement]],"Credit", btrn[2024-12-01])-SUMIF(btrn[[Movement]:[Movement]],"Debit",btrn[2024-12-01]) -> 790 | K15: =SUMIF(btrn[[Movement]:[Movement]],"Credit", btrn[2024-12-02])-SUMIF(btrn[[Movement]:[Movement]],"Debit",btrn[2024-12-02]) -> 790 | M15: =SUMIF(btrn[Movement], "Credit", btrn[2025-02-01]) - SUMIF(btrn[Movement], "Debit", btrn[2025-02-01]) -> 320 | N15: =SUMIF(btrn[Movement], "Credit", btrn[2025-03-01]) - SUMIF(btrn[Movement], "Debit", btrn[2025-03-01]) -> -483 | O15: =SUMIF(btrn[Movement], "Credit", btrn[2025-04-01]) - SUMIF(btrn[Movement], "Debit", btrn[2025-04-01]) -> 84 | P15: =SUMIF(btrn[Movement], "Credit", btrn[2025-05-01]) - SUMIF(btrn[Movement], "Debit", btrn[2025-05-01]) -> -564 | Q15: =SUMIF(btrn[Movement], "Credit", btrn[2025-06-01]) - SUMIF(btrn[Movement], "Debit", btrn[2025-06-01]) -> -1304 | R15: =SUMIF(btrn[Movement], "Credit", btrn[2025-07-01]) - SUMIF(btrn[Movement], "Debit", btrn[2025-07-01]) -> -12 | S15: =SUMIF(btrn[Movement], "Credit", btrn[2025-08-01]) - SUMIF(btrn[Movement], "Debit", btrn[2025-08-01]) -> 184 | T15: =SUMIF(btrn[Movement], "Credit", btrn[2025-09-01]) - SUMIF(btrn[Movement], "Debit", btrn[2025-09-01]) -> 334 | U15: =SUMIF(btrn[Movement], "Credit", btrn[2025-10-01]) - SUMIF(btrn[Movement], "Debit", btrn[2025-10-01]) -> 44 | V15: =SUMIF(btrn[Movement], "Credit", btrn[2025-11-01]) - SUMIF(btrn[Movement], "Debit", btrn[2025-11-01]) -> -6 | W15: =SUMIF(btrn[Movement], "Credit", btrn[2025-12-01]) - SUMIF(btrn[Movement], "Debit", btrn[2025-12-01]) -> -56

Sheet Bernice Credit Card
A1: Item | B1: Amount
A2: Interest NACM | B2: 0.1675
A3: Interst Monthly | B3: =B2/12 -> 0.013958333
A7: Movement | B7: Account Secondary | C7: 2024-05-01 | D7: 2024-06-01 | E7: 2024-07-01 | F7: 2024-08-01 | G7: 2024-09-01 | H7: 2024-10-01 | I7: 2024-11-01 | J7: 2024-12-01 | K7: 2025-02-01 | L7: 2025-03-01 | M7: 2025-04-01 | N7: 2025-05-01 | O7: 2025-06-01 | P7: 2025-07-01 | Q7: 2025-08-01 | R7: 2025-09-01 | S7: 2025-10-01 | T7: 2025-11-01 | U7: 2025-12-01
A8: Credit | B8: Bernice Transactional | C8: 2000 | D8: 0 | E8: 500 | F8: 500 | G8: 500 | H8: 500 | I8: 500 | J8: 500 | K8: 900 | L8: 1500 | M8: 2000 | N8: 2000 | O8: 2000 | P8: 2000 | Q8: 2000 | R8: 2000 | S8: 2000 | T8: 2000 | U8: 2000
A9: Credit | B9: Retained Balance | K9: -30 | L9: -1319 | M9: -4483 | N9: -3866 | O9: -2824 | P9: -5447 | Q9: -5447 | R9: =Q16 -> -7495.031 | S9: -7900 | T9: =S16 -> -6010.2708 | U9: =T16 -> -4094.1642
A10: Debit | B10: Interest | L10: =IF(L9 <= 0, (L9*$B$3)*-1, 0) -> 18.411042 | M10: =IF(M9 <= 0, (M9*$B$3)*-1, 0) -> 62.575208 | N10: =IF(N9 <= 0, (N9*$B$3)*-1, 0) -> 53.962917 | O10: =IF(O9 <= 0, (O9*$B$3)*-1, 0) -> 39.418333 | P10: =IF(P9 <= 0, (P9*$B$3)*-1, 0) -> 76.031042 | Q10: =IF(Q9 <= 0, (Q9*$B$3)*-1, 0) -> 76.031042 | R10: =IF(R9 <= 0, (R9*$B$3)*-1, 0) -> 104.61814 | S10: =IF(S9 <= 0, (S9*$B$3)*-1, 0) -> 110.27083 | ... U10: =IF(U9 <= 0, (U9*$B$3)*-1, 0) -> 57.147709
A11: Debit | B11: Bulk Meat | E11: 3550 | K11: 3500 | L11: 0 | Q11: 3500
A12: Debit | B12: Geely Parts | K12: 1600
A13: Debit | B13: Other | C13: 0 | D13: 0 | E13: 0 | F13: 0 | G13: 0 | H13: 0 | I13: 0 | J13: 0 | K13: 1000 | P13: 300 | Q13: 472
A14: Debit | B14: Groceries | L14: 1873
A15: Debit | B15: Jeanre Transactional | L15: 2627
A16: Subtotal | B16: Bernice Credit Card | C16: =SUMIF(bcc_1[[Movement]:[Movement]],"Credit", bcc_1[2024-05-01])-SUMIF(bcc_1[[Movement]:[Movement]],"Debit",bcc_1[2024-05-01]) -> 2000 | D16: =SUMIF(bcc_1[[Movement]:[Movement]],"Credit", bcc_1[2024-06-01])-SUMIF(bcc_1[[Movement]:[Movement]],"Debit",bcc_1[2024-06-01]) -> 0 | E16: =SUMIF(bcc_1[[Movement]:[Movement]],"Credit", bcc_1[2024-07-01])-SUMIF(bcc_1[[Movement]:[Movement]],"Debit",bcc_1[2024-07-01]) -> -3050 | F16: =SUMIF(bcc_1[[Movement]:[Movement]],"Credit", bcc_1[2024-08-01])-SUMIF(bcc_1[[Movement]:[Movement]],"Debit",bcc_1[2024-08-01]) -> 500 | G16: =SUMIF(bcc_1[[Movement]:[Movement]],"Credit", bcc_1[2024-09-01])-SUMIF(bcc_1[[Movement]:[Movement]],"Debit",bcc_1[2024-09-01]) -> 500 | H16: =SUMIF(bcc_1[[Movement]:[Movement]],"Credit", bcc_1[2024-10-01])-SUMIF(bcc_1[[Movement]:[Movement]],"Debit",bcc_1[2024-10-01]) -> 500 | I16: =SUMIF(bcc_1[[Movement]:[Movement]],"Credit", bcc_1[2024-11-01])-SUMIF(bcc_1[[Movement]:[Movement]],"Debit",bcc_1[2024-11-01]) -> 500 | J16: =SUMIF(bcc_1[[Movement]:[Movement]],"Credit", bcc_1[2024-12-01])-SUMIF(bcc_1[[Movement]:[Movement]],"Debit",bcc_1[2024-12-01]) -> 500 | K16: =SUMIF(bcc_1[Movement], "Credit", bcc_1[2025-02-01]) - SUMIF(bcc_1[Movement], "Debit", bcc_1[2025-02-01]) -> -5230 | L16: =SUMIF(bcc_1[Movement], "Credit", bcc_1[2025-03-01]) - SUMIF(bcc_1[Movement], "Debit", bcc_1[2025-03-01]) -> -4337.411 | M16: =SUMIF(bcc_1[Movement], "Credit", bcc_1[2025-04-01]) - SUMIF(bcc_1[Movement], "Debit", bcc_1[2025-04-01]) -> -2545.5752 | N16: =SUMIF(bcc_1[Movement], "Credit", bcc_1[2025-05-01]) - SUMIF(bcc_1[Movement], "Debit", bcc_1[2025-05-01]) -> -1919.9629 | O16: =SUMIF(bcc_1[Movement], "Credit", bcc_1[2025-06-01]) - SUMIF(bcc_1[Movement], "Debit", bcc_1[2025-06-01]) -> -863.41833 | P16: =SUMIF(bcc_1[Movement], "Credit", bcc_1[2025-07-01]) - SUMIF(bcc_1[Movement], "Debit", bcc_1[2025-07-01]) -> -3823.031 | Q16: =SUMIF(bcc_1[Movement], "Credit", bcc_1[2025-08-01]) - SUMIF(bcc_1[Movement], "Debit", bcc_1[2025-08-01]) -> -7495.031 | R16: =SUMIF(bcc_1[Movement], "Credit", bcc_1[2025-09-01]) - SUMIF(bcc_1[Movement], "Debit", bcc_1[2025-09-01]) -> -5599.6492 | S16: =SUMIF(bcc_1[Movement], "Credit", bcc_1[2025-10-01]) - SUMIF(bcc_1[Movement], "Debit", bcc_1[2025-10-01]) -> -6010.2708 | T16: =SUMIF(bcc_1[Movement], "Credit", bcc_1[2025-11-01]) - SUMIF(bcc_1[Movement], "Debit", bcc_1[2025-11-01]) -> -4094.1642 | U16: =SUMIF(bcc_1[Movement], "Credit", bcc_1[2025-12-01]) - SUMIF(bcc_1[Movement], "Debit", bcc_1[2025-12-01]) -> -2151.3119
A17: Debit Total | B17: Bernice Credit Card | K17: =SUMIF(bcc_1[Movement], "Debit", bcc_1[2025-02-01]) -> 6100 | L17: =SUMIF(bcc_1[Movement], "Debit", bcc_1[2025-03-01]) -> 4518.411 | M17: =SUMIF(bcc_1[Movement], "Debit", bcc_1[2025-04-01]) -> 62.575208 | N17: =SUMIF(bcc_1[Movement], "Debit", bcc_1[2025-05-01]) -> 53.962917 | O17: =SUMIF(bcc_1[Movement], "Debit", bcc_1[2025-06-01]) -> 39.418333 | P17: =SUMIF(bcc_1[Movement], "Debit", bcc_1[2025-07-01]) -> 376.03104 | Q17: =SUMIF(bcc_1[Movement], "Debit", bcc_1[2025-08-01]) -> 4048.031 | R17: =SUMIF(bcc_1[Movement], "Debit", bcc_1[2025-09-01]) -> 104.61814 | S17: =SUMIF(bcc_1[Movement], "Debit", bcc_1[2025-10-01]) -> 110.27083 | T17: =SUMIF(bcc_1[Movement], "Debit", bcc_1[2025-11-01]) -> 83.893364 | U17: =SUMIF(bcc_1[Movement], "Debit", bcc_1[2025-12-01]) -> 57.147709

Sheet Child
A1: Month | B1: Geely | C1: Self | D1: Month Total | E1: Costs Total | F1: Running Total | G1: Running Total + Interest | H1: Verified | I1: Interest Rate (NACM) | J1: 0.04
A2: 45839 | B2: 3000 | D2: =SUM(B2:C2) -> 3000 | F2: =SUM(B2:C2)-E2 -> 3000 | G2: =F2*(1+$J$2) -> 3010 | I2: IR per Month | J2: =J1/12 -> 0.0033333333 | N2: Current Month | O2: Agreed Payments | S2: Actuals (paid in Arrears)
A3: 45870 | D3: =SUM(B3:C3) -> 0 | F3: =SUM(B3:C3)-E3+F2 -> 3000 | G3: =F3*(1+$J$2) -> 3010 | O3: # | P3: Month | Q3: amount (agreed) | R3: Balance (predicted) | S3: amount Paid | T3: Balance (Actual) | U3: Overdue | V3: Payment Date | W3: Notes
A4: 45901 | C4: 1500 | D4: =SUM(B4:C4) -> 1500 | F4: =SUM(B4:C4)-E4+F3 -> 4500 | G4: =F4*(1+$J$2) -> 4515 | H4: Y | O4: 1 | P4: 45809 | Q4: 1500 | R4: 1500 | S4: 1500 | T4: 1500 | U4: =T4-R4 -> 0 | V4: 45804 | W4: technically paid in May
A5: 45931 | B5: 1500 | C5: 2000 | D5: =SUM(B5:C5) -> 3500 | F5: =SUM(B5:C5)-E5+F4 -> 8000 | G5: =F5*(1+$J$2) -> 8026.6667 | O5: 2 | P5: 45839 | Q5: 1500 | R5: =R4+Q5 -> 3000 | S5: 1500 | T5: =(T4+Table510[[#This Row],[amount Paid]]) -> 3000 | U5: =T5-R5 -> 0 | V5: 45845
A6: 45962 | B6: 1500 | C6: 2000 | D6: =SUM(B6:C6) -> 3500 | F6: =SUM(B6:C6)-E6+F5 -> 11500 | G6: =F6*(1+$J$2) -> 11538.333 | O6: 3 | P6: 45870 | Q6: 1500 | R6: =R5+Q6 -> 4500 | S6: 0 | T6: =(T5+Table510[[#This Row],[amount Paid]]) -> 3000 | U6: =T6-R6 -> -1500
A7: 45992 | B7: 1500 | C7: 2000 | D7: =SUM(B7:C7) -> 3500 | F7: =SUM(B7:C7)-E7+F6 -> 15000 | G7: =F7*(1+$J$2) -> 15050 | N7: Y | O7: 4 | P7: 45901 | Q7: 1500 | R7: =R6+Q7 -> 6000 | S7: 0 | T7: =(T6+Table510[[#This Row],[amount Paid]]) -> 3000 | U7: =T7-R7 -> -3000
A8: 46023 | B8: 1500 | C8: 2000 | D8: =SUM(B8:C8) -> 3500 | F8: =SUM(B8:C8)-E8+F7 -> 18500 | G8: =F8*(1+$J$2) -> 18561.667 | O8: 5 | P8: 45931 | Q8: 1500 | R8: =R7+Q8 -> 7500 | S8: 0 | T8: =(T7+Table510[[#This Row],[amount Paid]]) -> 3000 | U8: =T8-R8 -> -4500
A9: 46054 | B9: 1500 | C9: 2000 | D9: =SUM(B9:C9) -> 3500 | F9: =SUM(B9:C9)-E9+F8 -> 22000 | G9: =F9*(1+$J$2) -> 22073.333 | O9: 6 | P9: 45962 | Q9: 1500 | R9: =R8+Q9 -> 9000 | S9: 0 | T9: =(T8+Table510[[#This Row],[amount Paid]]) -> 3000 | U9: =T9-R9 -> -6000
A10: 46082 | B10: 1500 | C10: 2000 | D10: =SUM(B10:C10) -> 3500 | F10: =SUM(B10:C10)-E10+F9 -> 25500 | G10: =F10*(1+$J$2) -> 25585 | O10: 7 | P10: 45992 | Q10: 1500 | R10: =R9+Q10 -> 10500 | S10: 0 | T10: =(T9+Table510[[#This Row],[amount Paid]]) -> 3000 | U10: =T10-R10 -> -7500
A11: 46113 | B11: 1500 | C11: 2000 | D11: =SUM(B11:C11) -> 3500 | E11: 10000 | F11: =SUM(B11:C11)-E11+F10 -> 19000 | G11: =F11*(1+$J$2) -> 19063.333 | O11: 8 | P11: 46023 | Q11: 1500 | R11: =R10+Q11 -> 12000 | S11: 0 | T11: =(T10+Table510[[#This Row],[amount Paid]]) -> 3000 | U11: =T11-R11 -> -9000
A12: 46143 | B12: 1500 | C12: 2000 | D12: =SUM(B12:C12) -> 3500 | E12: 2000 | F12: =SUM(B12:C12)-E12+F11 -> 20500 | G12: =F12*(1+$J$2) -> 20568.333 | O12: 9 | P12: 46054 | Q12: 1500 | R12: =R11+Q12 -> 13500 | S12: 0 | T12: =(T11+Table510[[#This Row],[amount Paid]]) -> 3000 | U12: =T12-R12 -> -10500
A13: 46174 | B13: 1500 | C13: 2000 | D13: =SUM(B13:C13) -> 3500 | E13: 2000 | F13: =SUM(B13:C13)-E13+F12 -> 22000 | G13: =F13*(1+$J$2) -> 22073.333 | O13: 10 | P13: 46082 | Q13: 1500 | R13: =R12+Q13 -> 15000 | S13: 0 | T13: =(T12+Table510[[#This Row],[amount Paid]]) -> 3000 | U13: =T13-R13 -> -12000
A14: 46204 | B14: 1500 | C14: 2000 | D14: =SUM(B14:C14) -> 3500 | E14: 2000 | F14: =SUM(B14:C14)-E14+F13 -> 23500 | G14: =F14*(1+$J$2) -> 23578.333 | O14: 11 | P14: 46113 | Q14: 1500 | R14: =R13+Q14 -> 16500 | S14: 0 | T14: =(T13+Table510[[#This Row],[amount Paid]]) -> 3000 | U14: =T14-R14 -> -13500
A15: 46235 | B15: 1500 | C15: 2000 | D15: =SUM(B15:C15) -> 3500 | E15: 2000 | F15: =SUM(B15:C15)-E15+F14 -> 25000 | G15: =F15*(1+$J$2) -> 25083.333 | O15: 12 | P15: 46143 | Q15: 1500 | R15: =R14+Q15 -> 18000 | S15: 0 | T15: =(T14+Table510[[#This Row],[amount Paid]]) -> 3000 | U15: =T15-R15 -> -15000
A16: 46266 | B16: 1500 | C16: 2000 | D16: =SUM(B16:C16) -> 3500 | E16: 2000 | F16: =SUM(B16:C16)-E16+F15 -> 26500 | G16: =F16*(1+$J$2) -> 26588.333 | O16: 13 | P16: 46174 | Q16: 1500 | R16: =R15+Q16 -> 19500 | S16: 0 | T16: =(T15+Table510[[#This Row],[amount Paid]]) -> 3000 | U16: =T16-R16 -> -16500
A17: 46296 | B17: 1500 | C17: 2000 | D17: =SUM(B17:C17) -> 3500 | E17: 2000 | F17: =SUM(B17:C17)-E17+F16 -> 28000 | G17: =F17*(1+$J$2) -> 28093.333 | O17: 14 | P17: 46204 | Q17: 1500 | R17: =R16+Q17 -> 21000 | S17: 0 | T17: =(T16+Table510[[#This Row],[amount Paid]]) -> 3000 | U17: =T17-R17 -> -18000
A18: 46327 | B18: 1500 | C18: 2000 | D18: =SUM(B18:C18) -> 3500 | E18: 2000 | F18: =SUM(B18:C18)-E18+F17 -> 29500 | G18: =F18*(1+$J$2) -> 29598.333 | O18: 15 | P18: 46235 | Q18: 1500 | R18: =R17+Q18 -> 22500 | S18: 0 | T18: =(T17+Table510[[#This Row],[amount Paid]]) -> 3000 | U18: =T18-R18 -> -19500
A19: 46357 | B19: 1500 | C19: 2000 | D19: =SUM(B19:C19) -> 3500 | E19: 2000 | F19: =SUM(B19:C19)-E19+F18 -> 31000 | G19: =F19*(1+$J$2) -> 31103.333 | O19: 16 | P19: 46266 | Q19: 1500 | R19: =R18+Q19 -> 24000 | S19: 0 | T19: =(T18+Table510[[#This Row],[amount Paid]]) -> 3000 | U19: =T19-R19 -> -21000
A20: 46388 | B20: 0 | C20: 2000 | D20: =SUM(B20:C20) -> 2000 | E20: 2500 | F20: =SUM(B20:C20)-E20+F19 -> 30500 | G20: =F20*(1+$J$2) -> 30601.667 | O20: 17 | P20: 46296 | Q20: 1500 | R20: =R19+Q20 -> 25500 | S20: 0 | T20: =(T19+Table510[[#This Row],[amount Paid]]) -> 3000 | U20: =T20-R20 -> -22500
A21: 46419 | B21: 0 | C21: 2000 | D21: =SUM(B21:C21) -> 2000 | E21: 2500 | F21: =SUM(B21:C21)-E21+F20 -> 30000 | G21: =F21*(1+$J$2) -> 30100 | O21: 18 | P21: 46327 | Q21: 1500 | R21: =R20+Q21 -> 27000 | S21: 0 | T21: =(T20+Table510[[#This Row],[amount Paid]]) -> 3000 | U21: =T21-R21 -> -24000
A22: 46447 | B22: 0 | C22: 2000 | D22: =SUM(B22:C22) -> 2000 | E22: 2500 | F22: =SUM(B22:C22)-E22+F21 -> 29500 | G22: =F22*(1+$J$2) -> 29598.333 | O22: 19 | P22: 46357 | Q22: 1500 | R22: =R21+Q22 -> 28500 | S22: 0 | T22: =(T21+Table510[[#This Row],[amount Paid]]) -> 3000 | U22: =T22-R22 -> -25500
... A24: 46508 | B24: 0 | C24: 2000 | D24: =SUM(B24:C24) -> 2000 | E24: 2500 | F24: =SUM(B24:C24)-E24+F23 -> 28500 | G24: =F24*(1+$J$2) -> 28595 | O24: 21 | P24: 46419 | Q24: 1500 | R24: =R23+Q24 -> 31500 | S24: 0 | T24: =(T23+Table510[[#This Row],[amount Paid]]) -> 3000 | U24: =T24-R24 -> -28500
A25: 46539 | B25: 0 | C25: 2000 | D25: =SUM(B25:C25) -> 2000 | E25: 2500 | F25: =SUM(B25:C25)-E25+F24 -> 28000 | G25: =F25*(1+$J$2) -> 28093.333 | P25: 46447 | R25: =R24+Q25 -> 31500 | U25: =T25-R25 -> -31500
A26: 46569 | B26: 0 | C26: 2000 | D26: =SUM(B26:C26) -> 2000 | E26: 2500 | F26: =SUM(B26:C26)-E26+F25 -> 27500 | G26: =F26*(1+$J$2) -> 27591.667
A27: 46600 | B27: 0 | C27: 2000 | D27: =SUM(B27:C27) -> 2000 | E27: 2500 | F27: =SUM(B27:C27)-E27+F26 -> 27000 | G27: =F27*(1+$J$2) -> 27090
A28: 46631 | B28: 0 | C28: 2000 | D28: =SUM(B28:C28) -> 2000 | E28: 2500 | F28: =SUM(B28:C28)-E28+F27 -> 26500 | G28: =F28*(1+$J$2) -> 26588.333
A29: 46661 | B29: 0 | C29: 2000 | D29: =SUM(B29:C29) -> 2000 | E29: 2500 | F29: =SUM(B29:C29)-E29+F28 -> 26000 | G29: =F29*(1+$J$2) -> 26086.667
A30: 46692 | B30: 0 | C30: 2000 | D30: =SUM(B30:C30) -> 2000 | E30: 2500 | F30: =SUM(B30:C30)-E30+F29 -> 25500 | G30: =F30*(1+$J$2) -> 25585
A31: 46722 | B31: 0 | C31: 2000 | D31: =SUM(B31:C31) -> 2000 | E31: 2500 | F31: =SUM(B31:C31)-E31+F30 -> 25000 | G31: =F31*(1+$J$2) -> 25083.333
A32: 46753 | B32: 0 | C32: 2000 | D32: =SUM(B32:C32) -> 2000 | E32: 3000 | F32: =SUM(B32:C32)-E32+F31 -> 24000 | G32: =F32*(1+$J$2) -> 24080
A33: 46784 | B33: 0 | C33: 2000 | D33: =SUM(B33:C33) -> 2000 | E33: 3000 | F33: =SUM(B33:C33)-E33+F32 -> 23000 | G33: =F33*(1+$J$2) -> 23076.667
A34: 46813 | B34: 0 | C34: 2000 | D34: =SUM(B34:C34) -> 2000 | E34: 3000 | F34: =SUM(B34:C34)-E34+F33 -> 22000 | G34: =F34*(1+$J$2) -> 22073.333
A35: 46844 | B35: 0 | C35: 2000 | D35: =SUM(B35:C35) -> 2000 | E35: 3000 | F35: =SUM(B35:C35)-E35+F34 -> 21000 | G35: =F35*(1+$J$2) -> 21070
A36: 46874 | B36: 0 | C36: 2000 | D36: =SUM(B36:C36) -> 2000 | E36: 3000 | F36: =SUM(B36:C36)-E36+F35 -> 20000 | G36: =F36*(1+$J$2) -> 20066.667
A37: 46905 | B37: 0 | C37: 2000 | D37: =SUM(B37:C37) -> 2000 | E37: 3000 | F37: =SUM(B37:C37)-E37+F36 -> 19000 | G37: =F37*(1+$J$2) -> 19063.333
A38: 46935 | B38: 0 | C38: 2000 | D38: =SUM(B38:C38) -> 2000 | E38: 3000 | F38: =SUM(B38:C38)-E38+F37 -> 18000 | G38: =F38*(1+$J$2) -> 18060
A39: 46966 | B39: 0 | C39: 2000 | D39: =SUM(B39:C39) -> 2000 | E39: 3000 | F39: =SUM(B39:C39)-E39+F38 -> 17000 | G39: =F39*(1+$J$2) -> 17056.667 | S39: =AM39+B39 -> 0
A40: 46997 | B40: 0 | C40: 2000 | D40: =SUM(B40:C40) -> 2000 | E40: 3000 | F40: =SUM(B40:C40)-E40+F39 -> 16000 | G40: =F40*(1+$J$2) -> 16053.333 | S40: =S39+B40 -> 0
A41: 47027 | B41: 0 | C41: 2000 | D41: =SUM(B41:C41) -> 2000 | E41: 3000 | F41: =SUM(B41:C41)-E41+F40 -> 15000 | G41: =F41*(1+$J$2) -> 15050 | S41: =S40+B41 -> 0 | T41: 18
...

Sheet Jodine U
A1: Item | B1: Value
A2: Interest(NACM) | B2: 0.025
A3: Interest Monthly | B3: =1+ B2/12 -> 1.0020833
A4: Total AIE per Semester | B4: 30000
A5: Min Deposit | B5: 5000
A6: registration | B6: 2000
A7: Remaining amount | B7: =B4-B5-B6 -> 23000
A8: Monthly Installment | B8: 10000
A9: Jodine Contribution | B9: 5000
A10: Jeanre Contribution | B10: 0
A12: Type | B12: Description | C12: Jan-25 | D12: Feb-25 | E12: Mar-25 | F12: Apr-25 | G12: May-25 | H12: Jun-25 | I12: Jul-25 | J12: Aug-25 | K12: Sep-25 | L12: Oct-25 | M12: Nov-25 | N12: Dec-25 | O12: Jan-26 | P12: Feb-26 | Q12: Mar-26 | R12: Apr-26 | S12: May-26 | T12: Jun-26 | U12: Jul-26 | V12: Aug-26 | W12: Sep-26 | X12: Oct-26 | Y12: Nov-26 | Z12: Dec-26 | AA12: Jan-27 | AB12: Feb-27 | AC12: Mar-27 | AD12: Apr-27 | AE12: May-27 | AF12: Jun-27 | AG12: Jul-27 | AH12: Aug-27 | AI12: Sep-27 | AJ12: Oct-27 | AK12: Nov-27 | AL12: Dec-27 | AM12: Jan-28 | AN12: Feb-28 | AO12: Mar-28 | AP12: Apr-28 | AQ12: May-28 | AR12: Jun-28 | AS12: Jul-28 | AT12: Aug-28 | AU12: Sep-28 | AV12: Oct-28 | AW12: Nov-28 | AX12: Dec-28 | AY12: Jan-29 | AZ12: Feb-29 | BA12: Mar-29 | BB12: Apr-29 | BC12: May-29 | BD12: Jun-29 | BE12: Jul-29 | BF12: Aug-29 | BG12: Sep-29 | BH12: Oct-29 | BI12: Nov-29 | BJ12: Dec-29
A13: Income | B13: Jodine | D13: 4000 | E13: 4000 | F13: 4000 | G13: 5000 | H13: =$B$9 -> 5000 | I13: =$B$9 -> 5000 | L13: 10000 | M13: =$B$9 -> 5000 | N13: =$B$9 -> 5000 | O13: =$B$9 -> 5000 | P13: =$B$9 -> 5000 | Q13: =$B$9 -> 5000 | R13: =$B$9 -> 5000 | S13: =$B$9 -> 5000 | T13: =$B$9 -> 5000 | ... BJ13: =$B$9 -> 5000
A14: Income | B14: Jeanre | F14: =$B$10 -> 0 | G14: 1500 | H14: =$B$10 -> 0 | I14: 500 | J14: =$B$10 -> 0 | K14: =$B$10 -> 0 | L14: =$B$10 -> 0 | M14: =$B$10 -> 0 | N14: =$B$10 -> 0 | O14: =$B$10 -> 0 | P14: =$B$10 -> 0 | Q14: =$B$10 -> 0 | ... BJ14: =$B$10 -> 0
A15: Income | B15: Excess
A16: Income
A17: Income | B17: Retained Balance | C17: 1700 | D17: =C24 -> 1703.54 | E17: =D24 -> 5715.42 | F17: =E24 -> 9735.66 | G17: 15267.4 | H17: =G24 -> 21812.75 | I17: 21881.95 | J17: =I24 -> 23420.64 | K17: 18548 | L17: 18548 | M17: =L24 -> 24589.12 | N17: =M24 -> 25632.41 | O17: =N24 -> 26677.87 | P17: =O24 -> 19718.87 | Q17: =P24 -> 19759.95 | R17: =Q24 -> 19801.12 | S17: =R24 -> 19842.37 | T17: =S24 -> 19883.71 | ... BJ17: =BI24 -> 24545.54
A18: Expense | B18: Deposit | H18: 5000 | O18: 7000 | U18: =$B$5+$B$6 -> 7000 | AG18: 7000 | AS18: 7000
A19: Expense | B19: Monthly Payment | I19: 4010 | J19: 4010 | K19: 4010 | L19: 4010 | M19: 4010 | N19: 4010 | O19: 5000 | P19: 5000 | Q19: 5000 | R19: 5000 | S19: 5000 | T19: 5000 | U19: 5000 | V19: 5000 | W19: 5000 | X19: 5000 | Y19: 5000 | Z19: 5000 | AA19: 5000 | AB19: 5000 | AC19: 5000 | AD19: 5000 | AE19: 5000 | AF19: 5000 | AG19: 5000 | AH19: 5000 | AI19: 5000 | AJ19: 5000 | AK19: 5000 | AL19: 5000 | AM19: 5000 | AN19: 5000 | AO19: 5000 | AP19: 5000 | AQ19: 5000 | AR19: 5000 | AS19: 5000 | AT19: 5000 | AU19: 5000 | AV19: 5000 | AW19: 5000 | AX19: 5000 | AY19: 5000 | AZ19: 5000 | BA19: 5000 | BB19: 5000 | BC19: 5000 | BD19: 5000
A20: Expense | B20: Laptop
A21: Expense | B21: Books
A23: Total | C23: =(SUMIF(Table143911[Type],"Income",Table143911[Jan-25])-SUMIF(Table143911[Type],"Expense",Table143911[Jan-25])) -> 1700 | D23: =SUMIF(Table143911[Type],"Income",Table143911[Feb-25])-SUMIF(Table143911[Type],"Expense",Table143911[Feb-25]) -> 5703.54 | E23: =SUMIF(Table143911[Type],"Income",Table143911[Mar-25])-SUMIF(Table143911[Type],"Expense",Table143911[Mar-25]) -> 9715.42 | F23: =SUMIF(Table143911[Type],"Income",Table143911[Apr-25])-SUMIF(Table143911[Type],"Expense",Table143911[Apr-25]) -> 13735.66 | G23: =SUMIF(Table143911[Type],"Income",Table143911[May-25])-SUMIF(Table143911[Type],"Expense",Table143911[May-25]) -> 21767.4 | H23: =SUMIF(Table143911[Type],"Income",Table143911[Jun-25])-SUMIF(Table143911[Type],"Expense",Table143911[Jun-25]) -> 21812.75 | I23: =SUMIF(Table143911[Type],"Income",Table143911[Jul-25])-SUMIF(Table143911[Type],"Expense",Table143911[Jul-25]) -> 23371.95 | J23: =SUMIF(Table143911[Type],"Income",Table143911[Aug-25])-SUMIF(Table143911[Type],"Expense",Table143911[Aug-25]) -> 19410.64 | K23: =SUMIF(Table143911[Type],"Income",Table143911[Sep-25])-SUMIF(Table143911[Type],"Expense",Table143911[Sep-25]) -> 14538 | L23: =SUMIF(Table143911[Type],"Income",Table143911[Oct-25])-SUMIF(Table143911[Type],"Expense",Table143911[Oct-25]) -> 24538 | M23: =SUMIF(Table143911[Type],"Income",Table143911[Nov-25])-SUMIF(Table143911[Type],"Expense",Table143911[Nov-25]) -> 25579.12 | N23: =SUMIF(Table143911[Type],"Income",Table143911[Dec-25])-SUMIF(Table143911[Type],"Expense",Table143911[Dec-25]) -> 26622.41 | O23: =SUMIF(Table143911[Type],"Income",Table143911[Jan-26])-SUMIF(Table143911[Type],"Expense",Table143911[Jan-26]) -> 19677.87 | P23: =SUMIF(Table143911[Type],"Income",Table143911[Feb-26])-SUMIF(Table143911[Type],"Expense",Table143911[Feb-26]) -> 19718.87 | Q23: =SUMIF(Table143911[Type],"Income",Table143911[Mar-26])-SUMIF(Table143911[Type],"Expense",Table143911[Mar-26]) -> 19759.95 | R23: =SUMIF(Table143911[Type],"Income",Table143911[Apr-26])-SUMIF(Table143911[Type],"Expense",Table143911[Apr-26]) -> 19801.12 | S23: =SUMIF(Table143911[Type],"Income",Table143911[May-26])-SUMIF(Table143911[Type],"Expense",Table143911[May-26]) -> 19842.37 | T23: =SUMIF(Table143911[Type],"Income",Table143911[Jun-26])-SUMIF(Table143911[Type],"Expense",Table143911[Jun-26]) -> 19883.71 | U23: =SUMIF(Table143911[Type],"Income",Table143911[Jul-26])-SUMIF(Table143911[Type],"Expense",Table143911[Jul-26]) -> 12925.13 | V23: =SUMIF(Table143911[Type],"Income",Table143911[Aug-26])-SUMIF(Table143911[Type],"Expense",Table143911[Aug-26]) -> 12952.06 | W23: =SUMIF(Table143911[Type],"Income",Table143911[Sep-26])-SUMIF(Table143911[Type],"Expense",Table143911[Sep-26]) -> 12979.04 | X23: =SUMIF(Table143911[Type],"Income",Table143911[Oct-26])-SUMIF(Table143911[Type],"Expense",Table143911[Oct-26]) -> 13006.08 | Y23: =SUMIF(Table143911[Type],"Income",Table143911[Nov-26])-SUMIF(Table143911[Type],"Expense",Table143911[Nov-26]) -> 13033.18 | Z23: =SUMIF(Table143911[Type],"Income",Table143911[Dec-26])-SUMIF(Table143911[Type],"Expense",Table143911[Dec-26]) -> 13060.33 | AA23: =SUMIF(Table143911[Type],"Income",Table143911[Jan-27])-SUMIF(Table143911[Type],"Expense",Table143911[Jan-27]) -> 13087.54 | AB23: =SUMIF(Table143911[Type],"Income",Table143911[Feb-27])-SUMIF(Table143911[Type],"Expense",Table143911[Feb-27]) -> 13114.81 | AC23: =SUMIF(Table143911[Type],"Income",Table143911[Mar-27])-SUMIF(Table143911[Type],"Expense",Table143911[Mar-27]) -> 13142.13 | AD23: =SUMIF(Table143911[Type],"Income",Table143911[Apr-27])-SUMIF(Table143911[Type],"Expense",Table143911[Apr-27]) -> 13169.51 | AE23: =SUMIF(Table143911[Type],"Income",Table143911[May-27])-SUMIF(Table143911[Type],"Expense",Table143911[May-27]) -> 13196.95 | AF23: =SUMIF(Table143911[Type],"Income",Table143911[Jun-27])-SUMIF(Table143911[Type],"Expense",Table143911[Jun-27]) -> 13224.44 | AG23: =SUMIF(Table143911[Type],"Income",Table143911[Jul-27])-SUMIF(Table143911[Type],"Expense",Table143911[Jul-27]) -> 6251.99 | AH23: =SUMIF(Table143911[Type],"Income",Table143911[Aug-27])-SUMIF(Table143911[Type],"Expense",Table143911[Aug-27]) -> 6265.01 | AI23: =SUMIF(Table143911[Type],"Income",Table143911[Sep-27])-SUMIF(Table143911[Type],"Expense",Table143911[Sep-27]) -> 6278.06 | AJ23: =SUMIF(Table143911[Type],"Income",Table143911[Oct-27])-SUMIF(Table143911[Type],"Expense",Table143911[Oct-27]) -> 6291.14 | AK23: =SUMIF(Table143911[Type],"Income",Table143911[Nov-27])-SUMIF(Table143911[Type],"Expense",Table143911[Nov-27]) -> 6304.25 | AL23: =SUMIF(Table143911[Type],"Income",Table143911[Dec-27])-SUMIF(Table143911[Type],"Expense",Table143911[Dec-27]) -> 6317.38 | AM23: =SUMIF(Table143911[Type], "Income",Table143911[Jan-28])-SUMIF(Table143911[Type], "Expense",Table143911[Jan-28]) -> 6330.54 | AN23: =SUMIF(Table143911[Type], "Income",Table143911[Feb-28])-SUMIF(Table143911[Type], "Expense",Table143911[Feb-28]) -> 6343.73 | AO23: =SUMIF(Table143911[Type], "Income",Table143911[Mar-28])-SUMIF(Table143911[Type], "Expense",Table143911[Mar-28]) -> 6356.95 | AP23: =SUMIF(Table143911[Type], "Income",Table143911[Apr-28])-SUMIF(Table143911[Type], "Expense",Table143911[Apr-28]) -> 6370.19 | AQ23: =SUMIF(Table143911[Type], "Income",Table143911[May-28])-SUMIF(Table143911[Type], "Expense",Table143911[May-28]) -> 6383.46 | AR23: =SUMIF(Table143911[Type], "Income",Table143911[Jun-28])-SUMIF(Table143911[Type], "Expense",Table143911[Jun-28]) -> 6396.76 | AS23: =SUMIF(Table143911[Type], "Income",Table143911[Jul-28])-SUMIF(Table143911[Type], "Expense",Table143911[Jul-28]) -> -589.91 | AT23: =SUMIF(Table143911[Type], "Income",Table143911[Aug-28])-SUMIF(Table143911[Type], "Expense",Table143911[Aug-28]) -> -591.14 | AU23: =SUMIF(Table143911[Type], "Income",Table143911[Sep-28])-SUMIF(Table143911[Type], "Expense",Table143911[Sep-28]) -> -592.37 | AV23: =SUMIF(Table143911[Type], "Income",Table143911[Oct-28])-SUMIF(Table143911[Type], "Expense",Table143911[Oct-28]) -> -593.6 | AW23: =SUMIF(Table143911[Type], "Income",Table143911[Nov-28])-SUMIF(Table143911[Type], "Expense",Table143911[Nov-28]) -> -594.84 | AX23: =SUMIF(Table143911[Type], "Income",Table143911[Dec-28])-SUMIF(Table143911[Type], "Expense",Table143911[Dec-28]) -> -596.08 | AY23: =SUMIF(Table143911[Type], "Income",Table143911[Jan-29])-SUMIF(Table143911[Type], "Expense",Table143911[Jan-29]) -> -597.32 | AZ23: =SUMIF(Table143911[Type], "Income",Table143911[Feb-29])-SUMIF(Table143911[Type], "Expense",Table143911[Feb-29]) -> -598.56 | BA23: =SUMIF(Table143911[Type], "Income",Table143911[Mar-29])-SUMIF(Table143911[Type], "Expense",Table143911[Mar-29]) -> -599.81 | BB23: =SUMIF(Table143911[Type], "Income",Table143911[Apr-29])-SUMIF(Table143911[Type], "Expense",Table143911[Apr-29]) -> -601.06 | BC23: =SUMIF(Table143911[Type], "Income",Table143911[May-29])-SUMIF(Table143911[Type], "Expense",Table143911[May-29]) -> -602.31 | BD23: =SUMIF(Table143911[Type], "Income",Table143911[Jun-29])-SUMIF(Table143911[Type], "Expense",Table143911[Jun-29]) -> -603.56 | BE23: =SUMIF(Table143911[Type], "Income",Table143911[Jul-29])-SUMIF(Table143911[Type], "Expense",Table143911[Jul-29]) -> 4395.18 | BF23: =SUMIF(Table143911[Type], "Income",Table143911[Aug-29])-SUMIF(Table143911[Type], "Expense",Table143911[Aug-29]) -> 9404.34 | BG23: =SUMIF(Table143911[Type], "Income",Table143911[Sep-29])-SUMIF(Table143911[Type], "Expense",Table143911[Sep-29]) -> 14423.93 | BH23: =SUMIF(Table143911[Type], "Income",Table143911[Oct-29])-SUMIF(Table143911[Type], "Expense",Table143911[Oct-29]) -> 19453.98 | BI23: =SUMIF(Table143911[Type], "Income",Table143911[Nov-29])-SUMIF(Table143911[Type], "Expense",Table143911[Nov-29]) -> 24494.51 | BJ23: =SUMIF(Table143911[Type], "Income",Table143911[Dec-29])-SUMIF(Table143911[Type], "Expense",Table143911[Dec-29]) -> 29545.54
A24: Running Total w Interest | C24: =ROUND(Table143911[[#Totals],[Jan-25]]*$B$3,2) -> 1703.54 | D24: =ROUND(Table143911[[#Totals],[Feb-25]]*$B$3,2) -> 5715.42 | E24: =ROUND(Table143911[[#Totals],[Mar-25]]*$B$3,2) -> 9735.66 | F24: =ROUND(Table143911[[#Totals],[Apr-25]]*$B$3,2) -> 13764.28 | G24: =ROUND(Table143911[[#Totals],[May-25]]*$B$3,2) -> 21812.75 | H24: =ROUND(Table143911[[#Totals],[Jun-25]]*$B$3,2) -> 21858.19 | I24: =ROUND(Table143911[[#Totals],[Jul-25]]*$B$3,2) -> 23420.64 | J24: =ROUND(Table143911[[#Totals],[Aug-25]]*$B$3,2) -> 19451.08 | K24: =ROUND(Table143911[[#Totals],[Sep-25]]*$B$3,2) -> 14568.29 | L24: =ROUND(Table143911[[#Totals],[Oct-25]]*$B$3,2) -> 24589.12 | M24: =ROUND(Table143911[[#Totals],[Nov-25]]*$B$3,2) -> 25632.41 | N24: =ROUND(Table143911[[#Totals],[Dec-25]]*$B$3,2) -> 26677.87 | O24: =ROUND(Table143911[[#Totals],[Jan-26]]*$B$3,2) -> 19718.87 | P24: =ROUND(Table143911[[#Totals],[Feb-26]]*$B$3,2) -> 19759.95 | Q24: =ROUND(Table143911[[#Totals],[Mar-26]]*$B$3,2) -> 19801.12 | R24: =ROUND(Table143911[[#Totals],[Apr-26]]*$B$3,2) -> 19842.37 | S24: =ROUND(Table143911[[#Totals],[May-26]]*$B$3,2) -> 19883.71 | T24: =ROUND(Table143911[[#Totals],[Jun-26]]*$B$3,2) -> 19925.13 | U24: =ROUND(Table143911[[#Totals],[Jul-26]]*$B$3,2) -> 12952.06 | V24: =ROUND(Table143911[[#Totals],[Aug-26]]*$B$3,2) -> 12979.04 | W24: =ROUND(Table143911[[#Totals],[Sep-26]]*$B$3,2) -> 13006.08 | X24: =ROUND(Table143911[[#Totals],[Oct-26]]*$B$3,2) -> 13033.18 | Y24: =ROUND(Table143911[[#Totals],[Nov-26]]*$B$3,2) -> 13060.33 | Z24: =ROUND(Table143911[[#Totals],[Dec-26]]*$B$3,2) -> 13087.54 | AA24: =ROUND(Table143911[[#Totals],[Jan-27]]*$B$3,2) -> 13114.81 | AB24: =ROUND(Table143911[[#Totals],[Feb-27]]*$B$3,2) -> 13142.13 | AC24: =ROUND(Table143911[[#Totals],[Mar-27]]*$B$3,2) -> 13169.51 | AD24: =ROUND(Table143911[[#Totals],[Apr-27]]*$B$3,2) -> 13196.95 | AE24: =ROUND(Table143911[[#Totals],[May-27]]*$B$3,2) -> 13224.44 | AF24: =ROUND(Table143911[[#Totals],[Jun-27]]*$B$3,2) -> 13251.99 | AG24: =ROUND(Table143911[[#Totals],[Jul-27]]*$B$3,2) -> 6265.01 | AH24: =ROUND(Table143911[[#Totals],[Aug-27]]*$B$3,2) -> 6278.06 | AI24: =ROUND(Table143911[[#Totals],[Sep-27]]*$B$3,2) -> 6291.14 | AJ24: =ROUND(Table143911[[#Totals],[Oct-27]]*$B$3,2) -> 6304.25 | AK24: =ROUND(Table143911[[#Totals],[Nov-27]]*$B$3,2) -> 6317.38 | AL24: =ROUND(Table143911[[#Totals],[Dec-27]]*$B$3,2) -> 6330.54 | AM24: =ROUND(Table143911[[#Totals],[Jan-28]]*$B$3,2) -> 6343.73 | AN24: =ROUND(Table143911[[#Totals],[Feb-28]]*$B$3,2) -> 6356.95 | AO24: =ROUND(Table143911[[#Totals],[Mar-28]]*$B$3,2) -> 6370.19 | AP24: =ROUND(Table143911[[#Totals],[Apr-28]]*$B$3,2) -> 6383.46 | AQ24: =ROUND(Table143911[[#Totals],[May-28]]*$B$3,2) -> 6396.76 | AR24: =ROUND(Table143911[[#Totals],[Jun-28]]*$B$3,2) -> 6410.09 | AS24: =ROUND(Table143911[[#Totals],[Jul-28]]*$B$3,2) -> -591.14 | AT24: =ROUND(Table143911[[#Totals],[Aug-28]]*$B$3,2) -> -592.37 | AU24: =ROUND(Table143911[[#Totals],[Sep-28]]*$B$3,2) -> -593.6 | AV24: =ROUND(Table143911[[#Totals],[Oct-28]]*$B$3,2) -> -594.84 | AW24: =ROUND(Table143911[[#Totals],[Nov-28]]*$B$3,2) -> -596.08 | AX24: =ROUND(Table143911[[#Totals],[Dec-28]]*$B$3,2) -> -597.32 | AY24: =ROUND(Table143911[[#Totals],[Jan-29]]*$B$3,2) -> -598.56 | AZ24: =ROUND(Table143911[[#Totals],[Feb-29]]*$B$3,2) -> -599.81 | BA24: =ROUND(Table143911[[#Totals],[Mar-29]]*$B$3,2) -> -601.06 | BB24: =ROUND(Table143911[[#Totals],[Apr-29]]*$B$3,2) -> -602.31 | BC24: =ROUND(Table143911[[#Totals],[May-29]]*$B$3,2) -> -603.56 | BD24: =ROUND(Table143911[[#Totals],[Jun-29]]*$B$3,2) -> -604.82 | BE24: =ROUND(Table143911[[#Totals],[Jul-29]]*$B$3,2) -> 4404.34 | BF24: =ROUND(Table143911[[#Totals],[Aug-29]]*$B$3,2) -> 9423.93 | BG24: =ROUND(Table143911[[#Totals],[Sep-29]]*$B$3,2) -> 14453.98 | BH24: =ROUND(Table143911[[#Totals],[Oct-29]]*$B$3,2) -> 19494.51 | BI24: =ROUND(Table143911[[#Totals],[Nov-29]]*$B$3,2) -> 24545.54 | BJ24: =ROUND(Table143911[[#Totals],[Dec-29]]*$B$3,2) -> 29607.09
A25: verified accurate | F25: Y | G25: Y | I25: Y | K25: Y
