Workbook

Sheet Jeanre Transactional
A1: Movement | B1: Account Secondary | C1: 2024-05-01 | D1: 2024-06-01 | E1: 2024-07-01 | F1: 2024-08-01 | G1: 2024-09-01 | H1: 2024-10-01 | I1: 2024-11-01 | J1: 2024-12-01 | K1: 2025-01-01 | L1: 2025-02-01 | M1: 2025-03-01 | N1: 2025-04-01 | O1: 2025-05-01 | P1: 2025-06-01 | Q1: 2025-07-01 | R1: 2025-08-01 | S1: 2025-09-01 | T1: 2025-10-01 | U1: 2025-11-01 | V1: 2025-12-01
A2: Credit | B2: Salary | C2: 27000 | D2: 27000 | E2: 21600 | F2: 21600 | G2: 21600 | H2: 21600 | I2: 21600 | J2: 25100 | K2: 25100 | L2: 21600 | M2: 23100 | N2: 24600 | O2: 24600 | P2: 24600 | Q2: 24600 | R2: 24600 | S2: 24600 | T2: 24600 | U2: 24600 | V2: 24600
A3: Credit | B3: Bicycle Claims | C3: 1325 | D3: 1325 | E3: 1325 | F3: 1325 | G3: 1325 | H3: 1000 | I3: 1000 | J3: 1169 | K3: 1169 | L3: 1169 | M3: 1169 | N3: 1669 | O3: 1169 | P3: 1349 | Q3: 1419 | R3: 1169 | S3: 1169 | T3: 1169 | U3: 1169 | V3: 1169
A4: Credit | B4: Jodine Transactional | F4: 750 | G4: 1250 | I4: 250
A5: Credit | B5: Other
A6: Credit | B6: Personal Wealth | H6: 0 | I6: 3500
A7: Credit | B7: Retained Balance | M7: 259 | N7: 137 | O7: 0 | P7: 1024 | Q7: 900 | R7: =jtrn[[#Totals],[2025-07-01]] -> 135 | S7: =jtrn[[#Totals],[2025-08-01]] -> 1090 | T7: =jtrn[[#Totals],[2025-09-01]] -> 6145 | U7: =jtrn[[#Totals],[2025-10-01]] -> 6900 | V7: =jtrn[[#Totals],[2025-11-01]] -> 5655
A8: Credit | B8: Tax Refund | G8: 5700 | S8: 5000
A9: Credit | B9: Bernice Transactional | C9: 7700 | D9: 7700 | E9: 7000 | F9: 6800 | G9: 7000 | H9: 7300 | I9: 7750 | J9: 8000 | K9: 8000 | L9: 7700 | M9: 8000 | N9: 8000 | O9: 8000 | P9: 8000 | Q9: 8000 | R9: 8000 | S9: 8000 | T9: 8000 | U9: 8000 | V9: 8000
A10: Debit | B10: Jeanre Credit Card | C10: 500 | D10: 1500 | E10: 250 | F10: 500 | G10: 500 | H10: 1000 | I10: 750 | J10: 1000 | K10: 1000 | L10: 1000 | M10: 2000 | N10: 1700 | O10: 1000 | P10: 2000 | Q10: 1500 | R10: 2000 | S10: 2000 | T10: 2000 | U10: 2000 | V10: 2000
A11: Debit | B11: Home Loan | C11: 8140 | D11: 8140 | E11: 8140 | F11: 8140 | G11: 8140 | H11: 8140 | I11: 8140 | J11: 8140 | K11: 8140 | L11: 7910 | M11: 7795 | N11: 7795 | O11: 7795 | P11: 7795 | Q11: 7795 | R11: 7795 | S11: 7795 | T11: 7795 | U11: 7795 | V11: 7795
A12: Debit | B12: Vehicle Loan | C12: 3500 | D12: 3578 | E12: 3578 | F12: 3578 | G12: 3578 | H12: 3578 | I12: 3578 | J12: 3578 | K12: 3578 | L12: 3577 | M12: 3577 | N12: 3577 | O12: 3577 | P12: 3577 | Q12: 3577 | R12: 3577 | S12: 3577 | T12: 3577 | U12: 3577 | V12: 3577
A13: Debit | B13: Medical Aid | C13: 4530 | D13: 4530 | E13: 4530 | F13: 4530 | G13: 5600 | H13: 5600 | I13: 5600 | J13: 5600 | K13: 5600 | L13: 6305 | M13: 6305 | N13: 6305 | O13: 6305 | P13: 6305 | Q13: 6305 | R13: 6305 | S13: 6305 | T13: 6305 | U13: 6305 | V13: 6305
A14: Debit | B14: Netstar | C14: 110 | D14: 170 | E14: 170 | F14: 170 | G14: 170 | H14: 170 | I14: 170 | J14: 170 | K14: 170 | L14: 170 | M14: 170 | N14: 170 | O14: 170 | P14: 170 | Q14: 170 | R14: 170 | S14: 170 | T14: 170 | U14: 170 | V14: 170
A15: Debit | B15: Shortfall Insurance | C15: 117 | D15: 117 | E15: 117 | F15: 117 | G15: 117 | H15: 117 | I15: 117 | J15: 117 | K15: 117 | L15: 117 | M15: 117 | N15: 117 | O15: 117 | P15: 117 | Q15: 117 | R15: 117 | S15: 117 | T15: 117 | U15: 117 | V15: 117
A16: Debit | B16: Vehicle Insurance | C16: 1050 | D16: 988 | E16: 988 | F16: 988 | G16: 988 | H16: 988 | I16: 988 | J16: 988 | K16: 988 | L16: 988 | M16: 690 | N16: 690 | O16: 855 | P16: 690 | Q16: 690 | R16: 690 | S16: 690 | T16: 690 | U16: 690 | V16: 690
A17: Debit | B17: Home Insurance | C17: 1200 | D17: 560 | E17: 560 | F17: 560 | G17: 560 | H17: 560 | I17: 610 | J17: 610 | K17: 610 | L17: 610 | M17: 610 | N17: 610 | O17: 610 | P17: 610 | Q17: 610 | R17: 610 | S17: 610 | T17: 610 | U17: 610 | V17: 610
A18: Debit | B18: Life Insurance | C18: 440 | D18: 440 | E18: 440 | F18: 440 | G18: 440 | H18: 440 | I18: 440 | J18: 440 | K18: 440 | L18: 450 | M18: 450 | N18: 450 | O18: 450 | P18: 450 | Q18: 450 | R18: 450 | S18: 450 | T18: 450 | U18: 450 | V18: 450
A19: Debit | B19: Municipal Account | C19: 3500 | D19: 3500 | E19: 3500 | F19: 3500 | G19: 3500 | H19: 4000 | I19: 4000 | J19: 3700 | K19: 3700 | L19: 3000 | M19: 3200 | N19: 4726 | O19: 3260 | P19: 4100 | Q19: 3200 | R19: 3200 | S19: 3200 | T19: 3200 | U19: 3200 | V19: 3200
A20: Debit | B20: Internet | C20: 1000 | D20: 1000 | E20: 1000 | F20: 1000 | G20: 1000 | H20: 1000 | I20: 1000 | J20: 1000 | K20: 1000 | L20: 1000 | M20: 1000 | N20: 1000 | O20: 1000 | P20: 1000 | Q20: 1000 | R20: 1000 | S20: 1000 | T20: 1000 | U20: 1000 | V20: 1000
... A22: Debit | B22: Running Costs | C22: 5000 | D22: 4300 | E22: 3000 | F22: 3500 | G22: 3200 | H22: 3000 | I22: 3500 | J22: 4000 | K22: 4000 | L22: 2600 | M22: 3700 | N22: 3400 | O22: 3500 | P22: 3700 | Q22: 3500 | R22: 3700 | S22: 3700 | T22: 3700 | U22: 3700 | V22: 3700
A23: Debit | B23: Administration | C23: 0 | D23: 0 | E23: 0 | F23: 0 | G23: 0 | H23: 0 | I23: 0 | J23: 0 | K23: 0
A24: Debit | B24: Jodine Transactional | C24: 500 | D24: 200 | F24: 0 | G24: 0 | H24: 0 | I24: 0 | J24: 0 | K24: 0
A25: Debit | B25: Jodine U | C25: 1000 | D25: 1000 | E25: 0 | G25: 500 | H25: 1000 | I25: 500 | J25: 500 | K25: 500 | N25: 1500 | O25: 1500 | Q25: 500 | R25: 500 | S25: 500 | T25: 500 | U25: 500 | V25: 500
A26: Debit | B26: Emergency | C26: 200 | D26: 200 | E26: 200 | F26: 200 | G26: 200 | H26: 0 | I26: 200 | J26: 200 | K26: 200 | L26: 900 | M26: 400 | N26: 400 | O26: 400 | P26: 400 | Q26: 400 | R26: 400 | S26: 400 | T26: 400 | U26: 400 | V26: 400
A27: Debit | B27: Jeanre Retirement | C27: 0 | D27: 0 | E27: 0 | F27: 0 | G27: 0 | H27: 0 | I27: 0 | J27: 0 | K27: 0
A28: Debit | B28: Vehicle Licenses | E28: 640 | F28: 0 | G28: 0 | H28: 0 | I28: 0 | J28: 500 | K28: 500 | L28: 432 | Q28: 630
A29: Debit | B29: Other | E29: 600 | F29: 600 | H29: 580 | Q29: 250
A30: Debit | B30: Accounts | I30: 2227 | Q30: 1090
A31: Debit | B31: Events | I31: 2065 | U31: 2000
A32: Debit | B32: Medical | M32: 900 | N32: 500 | O32: 500 | P32: 500 | Q32: 900 | R32: 900 | S32: 900 | T32: 900 | U32: 900 | V32: 900
A33: Debit | B33: Tax | F33: 500 | G33: 500
A34: Debit | B34: Cell Phones | C34: 3100 | D34: 1700 | E34: 1820 | F34: 1820 | G34: 0 | H34: 0 | I34: 0 | J34: 0 | K34: 0
A35: Debit | B35: Jansie | C35: 600 | D35: 600 | E35: 0 | F35: 0 | G35: 0 | H35: 0 | I35: 0 | J35: 0 | K35: 0
A36: Debit | B36: Vape
A37: Debit | B37: Easy Equities | N37: 200 | O37: 200 | P37: 200 | Q37: 200 | R37: 200 | S37: 200 | T37: 200 | U37: 200 | V37: 200
A38: Debit | B38: Gas | L38: 700 | O38: 700 | S38: 700
A39: Debit | B39: Child Fund | Q39: 500
A40: Debit | B40: Personal Wealth | C40: 0 | D40: 500 | G40: 5000 | J40: 3000 | K40: 3000 | L40: 200 | M40: 500 | N40: 850 | O40: 900 | P40: 1000 | Q40: 1000 | R40: 800 | S40: 1000 | T40: 1000 | U40: 1000 | V40: 1000
A41: Subtotal | B41: Jeanre Transactional | C41: =SUMIF('Jeanre Transactional'!$A$2:$A$41,"Credit", 'Jeanre Transactional'!$C$2:$C$41)-SUMIF('Jeanre Transactional'!$A$2:$A$41,"Debit", 'Jeanre Transactional'!$C$2:$C$41) -> 538 | D41: =SUMIF('Jeanre Transactional'!$A$2:$A$41,"Credit", 'Jeanre Transactional'!$D$2:$D$41)-SUMIF('Jeanre Transactional'!$A$2:$A$41,"Debit", 'Jeanre Transactional'!$D$2:$D$41) -> 1502 | E41: =SUMIF('Jeanre Transactional'!$A$2:$A$41,"Credit", 'Jeanre Transactional'!$E$2:$E$41)-SUMIF('Jeanre Transactional'!$A$2:$A$41,"Debit", 'Jeanre Transactional'!$E$2:$E$41) -> 142 | F41: =SUMIF('Jeanre Transactional'!$A$2:$A$41,"Credit", 'Jeanre Transactional'!$F$2:$F$41)-SUMIF('Jeanre Transactional'!$A$2:$A$41,"Debit", 'Jeanre Transactional'!$F$2:$F$41) -> -168 | G41: =SUMIF('Jeanre Transactional'!$A$2:$A$41,"Credit", 'Jeanre Transactional'!$G$2:$G$41)-SUMIF('Jeanre Transactional'!$A$2:$A$41,"Debit", 'Jeanre Transactional'!$G$2:$G$41) -> 1982 | H41: =SUMIF('Jeanre Transactional'!$A$2:$A$41,"Credit", 'Jeanre Transactional'!$H$2:$H$41)-SUMIF('Jeanre Transactional'!$A$2:$A$41,"Debit", 'Jeanre Transactional'!$H$2:$H$41) -> -473 | I41: =SUMIF('Jeanre Transactional'!$A$2:$A$41,"Credit", 'Jeanre Transactional'!$I$2:$I$41)-SUMIF('Jeanre Transactional'!$A$2:$A$41,"Debit", 'Jeanre Transactional'!$I$2:$I$41) -> 65 | J41: =SUMIF('Jeanre Transactional'!$A$2:$A$41,"Credit", 'Jeanre Transactional'!$J$2:$J$41)-SUMIF('Jeanre Transactional'!$A$2:$A$41,"Debit", 'Jeanre Transactional'!$J$2:$J$41) -> -174 | K41: =SUMIF(jtrn[Movement], "Credit", jtrn[2025-01-01]) - SUMIF(jtrn[Movement], "Debit", jtrn[2025-01-01]) -> -174 | L41: =SUMIF(jtrn[Movement], "Credit", jtrn[2025-02-01]) - SUMIF(jtrn[Movement], "Debit", jtrn[2025-02-01]) -> 10 | M41: =SUMIF(jtrn[Movement], "Credit", jtrn[2025-03-01]) - SUMIF(jtrn[Movement], "Debit", jtrn[2025-03-01]) -> 614 | N41: =SUMIF(jtrn[Movement], "Credit", jtrn[2025-04-01]) - SUMIF(jtrn[Movement], "Debit", jtrn[2025-04-01]) -> 16 | O41: =SUMIF(jtrn[Movement], "Credit", jtrn[2025-05-01]) - SUMIF(jtrn[Movement], "Debit", jtrn[2025-05-01]) -> 530 | P41: =SUMIF(jtrn[Movement], "Credit", jtrn[2025-06-01]) - SUMIF(jtrn[Movement], "Debit", jtrn[2025-06-01]) -> 1359 | Q41: =SUMIF(jtrn[Movement], "Credit", jtrn[2025-07-01]) - SUMIF(jtrn[Movement], "Debit", jtrn[2025-07-01]) -> 135 | R41: =SUMIF(jtrn[Movement], "Credit", jtrn[2025-08-01]) - SUMIF(jtrn[Movement], "Debit", jtrn[2025-08-01]) -> 1090 | S41: =SUMIF(jtrn[Movement], "Credit", jtrn[2025-09-01]) - SUMIF(jtrn[Movement], "Debit", jtrn[2025-09-01]) -> 6145 | T41: =SUMIF(jtrn[Movement], "Credit", jtrn[2025-10-01]) - SUMIF(jtrn[Movement], "Debit", jtrn[2025-10-01]) -> 6900 | U41: =SUMIF(jtrn[Movement], "Credit", jtrn[2025-11-01]) - SUMIF(jtrn[Movement], "Debit", jtrn[2025-11-01]) -> 5655 | V41: =SUMIF(jtrn[Movement], "Credit", jtrn[2025-12-01]) - SUMIF(jtrn[Movement], "Debit", jtrn[2025-12-01]) -> 6410
...
